Workbook

Sheet MAPA DE VTR BPMA
A1: PREFIXO | B1: TOMBAMENTO | C1: TIPO | D1: EMPREGO | E1: MARCA | F1: MODELO | G1: ANO DE FABRICAÇÃO | H1: LOCALIZAÇÃO | I1: KM/HM ATUAL | J1: SITUAÇÃO | K1: MOTIVO DA BAIXA | L1: PLACA | M1: CHASSI | N1: TOMBAMENTO DO KIT SINALIZADOR | O1: TOMBAMENTO DO RÁDIO | P1: Nº DE SÉRIE DO RÁDIO | Q1: RESPONSÁVEL | R1: MODELO DO PNEU | S1: DATA DA ÚLTIMA TROCA DE PNEU | T1: KM DA PRÓXIMA TROCA DE PNEU | U1: KM/HM DA PRÓXIMA REVISÃO | V1: OBSERVAÇÕES
A2: 33548 | B2: 3600275753 | C2: CAMINHÃO | D2: ADMINISTRATIVO | E2: HYUNDAI | F2: HR 2.5 Turbo | G2: 2020/2021 | H2: SEDE BPMA | I2: {=IFERROR(XLOOKUP(A2,RESPOSTAS!B:B,RESPOSTAS!C:C,"",0,-1),"Sem valor")} | J2: {=IFERROR(XLOOKUP(A2,RESPOSTAS!B:B,RESPOSTAS!D:D,"",0,-1),"Sem valor")} -> Disponível | K2: {=IFERROR(XLOOKUP(A2,RESPOSTAS!B:B,RESPOSTAS!E:E,"",0,-1),"Sem valor")} | L2: RER-3C82 | M2: 95PZBN7KPMB090672 | N2: 3600275757 | O2: 3600212595 | P2: 16227A0403 | Q2: INDEFINIDO | R2: INDEFINIDO | S2: INDEFINIDO | U2: {=IFERROR(XLOOKUP(A2,RESPOSTAS!B:B,RESPOSTAS!F:F,"",0,-1),"Sem valor")}
A3: 55411 | B3: 3600175200 | C3: ÔNIBUS E VANS | D3: OPERACIONAL | E3: MARCOPOLO | F3: Volare W9 | G3: 2012 | H3: LACUSTRE | I3: {=IFERROR(XLOOKUP(A3,RESPOSTAS!B:B,RESPOSTAS!C:C,"",0,-1),"Sem valor")} | J3: {=IFERROR(XLOOKUP(A3,RESPOSTAS!B:B,RESPOSTAS!D:D,"",0,-1),"Sem valor")} -> Disponível | K3: {=IFERROR(XLOOKUP(A3,RESPOSTAS!B:B,RESPOSTAS!E:E,"",0,-1),"Sem valor")} | L3: JJU-1689 | M3: 93PB40N31CC042616 | N3: NÃO SE APLICA | O3: NÃO TEM | P3: NÃO SE APLICA | Q3: COPel | R3: INDEFINIDO | S3: INDEFINIDO | U3: {=IFERROR(XLOOKUP(A3,RESPOSTAS!B:B,RESPOSTAS!F:F,"",0,-1),"Sem valor")} | V3: ESTÁ COM O CURSO OP. LACUSTRES
A4: 55423 | B4: 3600175206 | C4: ÔNIBUS E VANS | D4: OPERACIONAL | E4: MARCOPOLO | F4: Volare W9 | G4: 2012 | H4: SEDE BPMA | I4: {=IFERROR(XLOOKUP(A4,RESPOSTAS!B:B,RESPOSTAS!C:C,"",0,-1),"Sem valor")} | J4: {=IFERROR(XLOOKUP(A4,RESPOSTAS!B:B,RESPOSTAS!D:D,"",0,-1),"Sem valor")} -> Disponível | K4: {=IFERROR(XLOOKUP(A4,RESPOSTAS!B:B,RESPOSTAS!E:E,"",0,-1),"Sem valor")} | L4: JJU-1799 | M4: 93PB40N31CC042633 | N4: NÃO SE APLICA | O4: NÃO TEM | P4: NÃO SE APLICA | Q4: INDEFINIDO | R4: INDEFINIDO | S4: INDEFINIDO | U4: {=IFERROR(XLOOKUP(A4,RESPOSTAS!B:B,RESPOSTAS!F:F,"",0,-1),"Sem valor")}
A5: 33183 | B5: 3600150586 | C5: TRATOR | D5: ADMINISTRATIVO | E5: AGRITECH | F5: 1175 | G5: 2010 | H5: LACUSTRE | I5: {=IFERROR(XLOOKUP(A5,RESPOSTAS!B:B,RESPOSTAS!C:C,"",0,-1),"Sem valor")} | J5: {=IFERROR(XLOOKUP(A5,RESPOSTAS!B:B,RESPOSTAS!D:D,"",0,-1),"Sem valor")} -> Disponível | K5: {=IFERROR(XLOOKUP(A5,RESPOSTAS!B:B,RESPOSTAS!E:E,"",0,-1),"Sem valor")} | L5: JKA4548 | M5: 71ON0247 | N5: NÃO SE APLICA | O5: NÃO TEM | P5: NÃO SE APLICA | Q5: LACUSTRE | R5: INDEFINIDO | S5: INDEFINIDO | U5: {=IFERROR(XLOOKUP(A5,RESPOSTAS!B:B,RESPOSTAS!F:F,"",0,-1),"Sem valor")} | V5: Trator usado para movimentar embarcações
A6: 77112 | B6: 3600153458 | C6: EMBARCAÇÃO | D6: OPERACIONAL | E6: YAMAHA | F6: Moto aquática Supercharged Intercooler | G6: 2011 | H6: LACUSTRE | I6: {=IFERROR(XLOOKUP(A6,RESPOSTAS!B:B,RESPOSTAS!C:C,"",0,-1),"Sem valor")} | J6: {=IFERROR(XLOOKUP(A6,RESPOSTAS!B:B,RESPOSTAS!D:D,"",0,-1),"Sem valor")} -> Sem informações | K6: {=IFERROR(XLOOKUP(A6,RESPOSTAS!B:B,RESPOSTAS!E:E,"",0,-1),"Sem valor")} | L6: JET-7112 | M6: US-YAMA2687B111 | N6: NÃO SE APLICA | O6: NÃO TEM | P6: NÃO SE APLICA | Q6: LACUSTRE | R6: NÃO SE APLICA | S6: NÃO SE APLICA | U6: {=IFERROR(XLOOKUP(A6,RESPOSTAS!B:B,RESPOSTAS!F:F,"",0,-1),"Sem valor")} | V6: JET VII
A7: 77111 | B7: 3600153460 | C7: EMBARCAÇÃO | D7: OPERACIONAL | E7: YAMAHA | F7: Moto aquática Supercharged Intercooler | G7: 2011 | H7: LACUSTRE | I7: {=IFERROR(XLOOKUP(A7,RESPOSTAS!B:B,RESPOSTAS!C:C,"",0,-1),"Sem valor")} | J7: {=IFERROR(XLOOKUP(A7,RESPOSTAS!B:B,RESPOSTAS!D:D,"",0,-1),"Sem valor")} -> Sem informações | K7: {=IFERROR(XLOOKUP(A7,RESPOSTAS!B:B,RESPOSTAS!E:E,"",0,-1),"Sem valor")} | L7: JET-7111 | M7: US-YAMA2711B111 | N7: NÃO SE APLICA | O7: NÃO TEM | P7: NÃO SE APLICA | Q7: LACUSTRE | R7: NÃO SE APLICA | S7: NÃO SE APLICA | U7: {=IFERROR(XLOOKUP(A7,RESPOSTAS!B:B,RESPOSTAS!F:F,"",0,-1),"Sem valor")} | V7: JET VIII
A8: 77121 | B8: 3600154371 | C8: EMBARCAÇÃO | D8: OPERACIONAL | E8: FLEXBOAT | F8: SR760 2MP | G8: 2011 | H8: LACUSTRE | I8: {=IFERROR(XLOOKUP(A8,RESPOSTAS!B:B,RESPOSTAS!C:C,"",0,-1),"Sem valor")} | J8: {=IFERROR(XLOOKUP(A8,RESPOSTAS!B:B,RESPOSTAS!D:D,"",0,-1),"Sem valor")} -> Sem informações | K8: {=IFERROR(XLOOKUP(A8,RESPOSTAS!B:B,RESPOSTAS!E:E,"",0,-1),"Sem valor")} | L8: BPA-7121 | M8: 171 | N8: NÃO SE APLICA | O8: NÃO TEM | P8: NÃO SE APLICA | Q8: LACUSTRE | R8: NÃO SE APLICA | S8: NÃO SE APLICA | U8: {=IFERROR(XLOOKUP(A8,RESPOSTAS!B:B,RESPOSTAS!F:F,"",0,-1),"Sem valor")} | V8: BPMA 01/ 1 motor
A9: 77117 | B9: 3600159566 | C9: EMBARCAÇÃO | D9: OPERACIONAL | E9: FLEXBOAT | F9: SR760 2MP | G9: 2011 | H9: LACUSTRE | I9: {=IFERROR(XLOOKUP(A9,RESPOSTAS!B:B,RESPOSTAS!C:C,"",0,-1),"Sem valor")} | J9: {=IFERROR(XLOOKUP(A9,RESPOSTAS!B:B,RESPOSTAS!D:D,"",0,-1),"Sem valor")} -> Sem informações | K9: {=IFERROR(XLOOKUP(A9,RESPOSTAS!B:B,RESPOSTAS!E:E,"",0,-1),"Sem valor")} | L9: BPM-7117 | M9: 173 | N9: NÃO SE APLICA | O9: NÃO TEM | P9: NÃO SE APLICA | Q9: LACUSTRE | R9: NÃO SE APLICA | S9: NÃO SE APLICA | U9: {=IFERROR(XLOOKUP(A9,RESPOSTAS!B:B,RESPOSTAS!F:F,"",0,-1),"Sem valor")} | V9: BPMA 03/ 2 motores
A10: 77118 | B10: 3600159574 | C10: EMBARCAÇÃO | D10: OPERACIONAL | E10: FLEXBOAT | F10: SR760 2MP | G10: 2011 | H10: LACUSTRE | I10: {=IFERROR(XLOOKUP(A10,RESPOSTAS!B:B,RESPOSTAS!C:C,"",0,-1),"Sem valor")} | J10: {=IFERROR(XLOOKUP(A10,RESPOSTAS!B:B,RESPOSTAS!D:D,"",0,-1),"Sem valor")} -> Sem informações | K10: {=IFERROR(XLOOKUP(A10,RESPOSTAS!B:B,RESPOSTAS!E:E,"",0,-1),"Sem valor")} | L10: BPM-0571 | M10: 175 | N10: NÃO SE APLICA | O10: NÃO TEM | P10: NÃO SE APLICA | Q10: LACUSTRE | R10: NÃO SE APLICA | S10: NÃO SE APLICA | U10: {=IFERROR(XLOOKUP(A10,RESPOSTAS!B:B,RESPOSTAS!F:F,"",0,-1),"Sem valor")} | V10: BOPÃO (BPMA 05)/ 2 motores
A11: 77119 | B11: 3600159578 | C11: EMBARCAÇÃO | D11: OPERACIONAL | E11: TRITON | F11: Barco com casco em fibra de vidro | G11: INDEFINIDO | H11: LACUSTRE | I11: {=IFERROR(XLOOKUP(A11,RESPOSTAS!B:B,RESPOSTAS!C:C,"",0,-1),"Sem valor")} | J11: {=IFERROR(XLOOKUP(A11,RESPOSTAS!B:B,RESPOSTAS!D:D,"",0,-1),"Sem valor")} -> Sem informações | K11: {=IFERROR(XLOOKUP(A11,RESPOSTAS!B:B,RESPOSTAS!E:E,"",0,-1),"Sem valor")} | L11: NÃO TEM | M11: BRWAY00896.D.111 | N11: NÃO SE APLICA | O11: NÃO TEM | P11: NÃO SE APLICA | Q11: LACUSTRE | R11: NÃO SE APLICA | S11: NÃO SE APLICA | U11: {=IFERROR(XLOOKUP(A11,RESPOSTAS!B:B,RESPOSTAS!F:F,"",0,-1),"Sem valor")} | V11: Triton
A12: 552942 | B12: 3600182242 | C12: ÔNIBUS E VANS | D12: OPERACIONAL | E12: FIAT | F12: Ducato Multi TA 2.3 | G12: 2012/2013 | H12: PREALG | I12: {=IFERROR(XLOOKUP(A12,RESPOSTAS!B:B,RESPOSTAS!C:C,"",0,-1),"Sem valor")} | J12: {=IFERROR(XLOOKUP(A12,RESPOSTAS!B:B,RESPOSTAS!D:D,"",0,-1),"Sem valor")} -> Indisponível | K12: {=IFERROR(XLOOKUP(A12,RESPOSTAS!B:B,RESPOSTAS!E:E,"",0,-1),"Sem valor")} | L12: 18 | M12: 93W245H34D2106396 | N12: NÃO SE APLICA | O12: 3600213121 | P12: 16227D0117 | Q12: INDEFINIDO | R12: INDEFINIDO | S12: INDEFINIDO | U12: {=IFERROR(XLOOKUP(A12,RESPOSTAS!B:B,RESPOSTAS!F:F,"",0,-1),"Sem valor")}
A13: 554285 | B13: 3600275708 | C13: ÔNIBUS E VANS | D13: OPERACIONAL | E13: RENAULT | F13: Master Vitre Pack luxo | G13: 2020/2021 | H13: PREALG | I13: {=IFERROR(XLOOKUP(A13,RESPOSTAS!B:B,RESPOSTAS!C:C,"",0,-1),"Sem valor")} | J13: {=IFERROR(XLOOKUP(A13,RESPOSTAS!B:B,RESPOSTAS!D:D,"",0,-1),"Sem valor")} -> Disponível | K13: {=IFERROR(XLOOKUP(A13,RESPOSTAS!B:B,RESPOSTAS!E:E,"",0,-1),"Sem valor")} | L13: REQ-8E50 | M13: 93YMAF4XEMJ784472 | N13: 3600275743 | O13: 3600213007 | P13: 16227D0003 | Q13: INDEFINIDO | R13: INDEFINIDO | S13: INDEFINIDO | U13: {=IFERROR(XLOOKUP(A13,RESPOSTAS!B:B,RESPOSTAS!F:F,"",0,-1),"Sem valor")} | V13: 16 PASSAGEIROS
A14: 442065 | B14: 3600258744 | C14: VTR 2 RODAS | D14: ADMINISTRATIVO | E14: YAMAHA | F14: LANDER XTZ 250 CC | G14: 2020/2021 | H14: SEDE BPMA | I14: {=IFERROR(XLOOKUP(A14,RESPOSTAS!B:B,RESPOSTAS!C:C,"",0,-1),"Sem valor")} | J14: {=IFERROR(XLOOKUP(A14,RESPOSTAS!B:B,RESPOSTAS!D:D,"",0,-1),"Sem valor")} -> Disponível | K14: {=IFERROR(XLOOKUP(A14,RESPOSTAS!B:B,RESPOSTAS!E:E,"",0,-1),"Sem valor")} | L14: REI-7I45 | M14: 9C6DG3320M0031053 | N14: 3600258844 | O14: NÃO TEM | P14: NÃO SE APLICA | Q14: SGT LUIZ REZENDE | R14: INDEFINIDO | S14: INDEFINIDO | U14: {=IFERROR(XLOOKUP(A14,RESPOSTAS!B:B,RESPOSTAS!F:F,"",0,-1),"Sem valor")}
A15: 442066 | B15: 3600258745 | C15: VTR 2 RODAS | D15: ADMINISTRATIVO | E15: YAMAHA | F15: LANDER XTZ 250 CC | G15: 2020/2021 | H15: SEDE BPMA | I15: {=IFERROR(XLOOKUP(A15,RESPOSTAS!B:B,RESPOSTAS!C:C,"",0,-1),"Sem valor")} | J15: {=IFERROR(XLOOKUP(A15,RESPOSTAS!B:B,RESPOSTAS!D:D,"",0,-1),"Sem valor")} -> Disponível | K15: {=IFERROR(XLOOKUP(A15,RESPOSTAS!B:B,RESPOSTAS!E:E,"",0,-1),"Sem valor")} | L15: REI-7I26 | M15: 9C6DG3320M0031094 | N15: 3600258845 | O15: NÃO TEM | P15: NÃO SE APLICA | Q15: DISPONÍVEL | R15: INDEFINIDO | S15: INDEFINIDO | U15: {=IFERROR(XLOOKUP(A15,RESPOSTAS!B:B,RESPOSTAS!F:F,"",0,-1),"Sem valor")}
A16: 554496 | B16: 200198856 | C16: VTR 4 RODAS | D16: OPERACIONAL | E16: CHEVROLET | F16: S10 LT DD4A | G16: 2022 | H16: INDEFINIDO | I16: {=IFERROR(XLOOKUP(A16,RESPOSTAS!B:B,RESPOSTAS!C:C,"",0,-1),"Sem valor")} | J16: {=IFERROR(XLOOKUP(A16,RESPOSTAS!B:B,RESPOSTAS!D:D,"",0,-1),"Sem valor")} -> Disponível | K16: {=IFERROR(XLOOKUP(A16,RESPOSTAS!B:B,RESPOSTAS!E:E,"",0,-1),"Sem valor")} | L16: SGP2C23 | M16: 9BG148FK0NC454139 | N16: NÃO TEM TOMBAMENTO | O16: INDEFINIDO | P16: INDEFINIDO | Q16: INDEFINIDO | R16: INDEFINIDO | S16: INDEFINIDO | U16: {=IFERROR(XLOOKUP(A16,RESPOSTAS!B:B,RESPOSTAS!F:F,"",0,-1),"Sem valor")} | V16: DO CPU
A17: 554544 | B17: 200199058 | C17: VTR 4 RODAS | D17: OPERACIONAL | E17: MITSUBISHI | F17: L200 TRITON | G17: 2023 | H17: SEDE BPMA | I17: {=IFERROR(XLOOKUP(A17,RESPOSTAS!B:B,RESPOSTAS!C:C,"",0,-1),"Sem valor")} | J17: {=IFERROR(XLOOKUP(A17,RESPOSTAS!B:B,RESPOSTAS!D:D,"",0,-1),"Sem valor")} -> Disponível | K17: {=IFERROR(XLOOKUP(A17,RESPOSTAS!B:B,RESPOSTAS!E:E,"",0,-1),"Sem valor")} | L17: SSF8H49 | M17: 93XTYKL1TRCP78273 | N17: NÃO TEM TOMBAMENTO | O17: INDEFINIDO | P17: INDEFINIDO | Q17: INDEFINIDO | R17: INDEFINIDO | S17: INDEFINIDO | U17: {=IFERROR(XLOOKUP(A17,RESPOSTAS!B:B,RESPOSTAS!F:F,"",0,-1),"Sem valor")}
A18: 554545 | B18: 200199059 | C18: VTR 4 RODAS | D18: OPERACIONAL | E18: MITSUBISHI | F18: L200 TRITON | G18: 2023 | H18: SEDE BPMA | I18: {=IFERROR(XLOOKUP(A18,RESPOSTAS!B:B,RESPOSTAS!C:C,"",0,-1),"Sem valor")} | J18: {=IFERROR(XLOOKUP(A18,RESPOSTAS!B:B,RESPOSTAS!D:D,"",0,-1),"Sem valor")} -> Disponível | K18: {=IFERROR(XLOOKUP(A18,RESPOSTAS!B:B,RESPOSTAS!E:E,"",0,-1),"Sem valor")} | L18: SSF8H42 | M18: 93XTYKL1TRCP78219 | N18: NÃO TEM TOMBAMENTO | O18: INDEFINIDO | P18: INDEFINIDO | Q18: SVG | R18: INDEFINIDO | S18: INDEFINIDO | U18: {=IFERROR(XLOOKUP(A18,RESPOSTAS!B:B,RESPOSTAS!F:F,"",0,-1),"Sem valor")}
A19: 552520 | B19: 3600176276 | C19: VTR 4 RODAS | D19: VELADO | E19: MITSUBISHI | F19: PAJERO DAKAR 3.2L | G19: 2012/2013 | H19: SEDE BPMA | I19: {=IFERROR(XLOOKUP(A19,RESPOSTAS!B:B,RESPOSTAS!C:C,"",0,-1),"Sem valor")} | J19: {=IFERROR(XLOOKUP(A19,RESPOSTAS!B:B,RESPOSTAS!D:D,"",0,-1),"Sem valor")} -> Indisponível | K19: {=IFERROR(XLOOKUP(A19,RESPOSTAS!B:B,RESPOSTAS!E:E,"",0,-1),"Sem valor")} | L19: INDEFINIDO | M19: 93XJNKH8WDCC08309 | N19: NÃO SE APLICA | O19: NÃO TEM | P19: NÃO SE APLICA | Q19: SEDE BPMA | U19: {=IFERROR(XLOOKUP(A19,RESPOSTAS!B:B,RESPOSTAS!F:F,"",0,-1),"Sem valor")} | V19: Que veio do pátio de leilão
A20: 553218 | B20: 3600205299 | C20: VTR 4 RODAS | D20: OPERACIONAL | E20: CHEVROLET | F20: S10 | G20: 2014 | H20: SEDE BPMA | I20: {=IFERROR(XLOOKUP(A20,RESPOSTAS!B:B,RESPOSTAS!C:C,"",0,-1),"Sem valor")} | J20: {=IFERROR(XLOOKUP(A20,RESPOSTAS!B:B,RESPOSTAS!D:D,"",0,-1),"Sem valor")} -> Descarga | K20: {=IFERROR(XLOOKUP(A20,RESPOSTAS!B:B,RESPOSTAS!E:E,"",0,-1),"Sem valor")} | L20: OVS-8850 | M20: 9BG148FK0EC432902 | N20: NÃO SE APLICA | O20: NÃO TEM | P20: NÃO SE APLICA | Q20: INDEFINIDO | R20: INDEFINIDO | S20: INDEFINIDO | U20: {=IFERROR(XLOOKUP(A20,RESPOSTAS!B:B,RESPOSTAS!F:F,"",0,-1),"Sem valor")}
A21: 553206 | B21: 3600205300 | C21: VTR 4 RODAS | D21: OPERACIONAL | E21: CHEVROLET | F21: S10 | G21: 2014 | H21: SEDE BPMA | I21: {=IFERROR(XLOOKUP(A21,RESPOSTAS!B:B,RESPOSTAS!C:C,"",0,-1),"Sem valor")} | J21: {=IFERROR(XLOOKUP(A21,RESPOSTAS!B:B,RESPOSTAS!D:D,"",0,-1),"Sem valor")} -> Disponível | K21: {=IFERROR(XLOOKUP(A21,RESPOSTAS!B:B,RESPOSTAS!E:E,"",0,-1),"Sem valor")} | L21: OVS-9707 | M21: 9BG148FK0EC436835 | N21: NÃO SE APLICA | O21: NÃO TEM | P21: NÃO SE APLICA | Q21: INDEFINIDO | R21: INDEFINIDO | S21: INDEFINIDO | U21: {=IFERROR(XLOOKUP(A21,RESPOSTAS!B:B,RESPOSTAS!F:F,"",0,-1),"Sem valor")}
A22: 553210 | B22: 3600205301 | C22: VTR 4 RODAS | D22: OPERACIONAL | E22: CHEVROLET | F22: S10 | G22: 2014 | H22: SEDE BPMA | I22: {=IFERROR(XLOOKUP(A22,RESPOSTAS!B:B,RESPOSTAS!C:C,"",0,-1),"Sem valor")} | J22: {=IFERROR(XLOOKUP(A22,RESPOSTAS!B:B,RESPOSTAS!D:D,"",0,-1),"Sem valor")} -> Disponível | K22: {=IFERROR(XLOOKUP(A22,RESPOSTAS!B:B,RESPOSTAS!E:E,"",0,-1),"Sem valor")} | L22: OVS-9715 | M22: 9BG148FK0EC444057 | N22: NÃO SE APLICA | O22: NÃO TEM | P22: NÃO SE APLICA | Q22: INDEFINIDO | R22: INDEFINIDO | S22: INDEFINIDO | U22: {=IFERROR(XLOOKUP(A22,RESPOSTAS!B:B,RESPOSTAS!F:F,"",0,-1),"Sem valor")}
A23: 553200 | B23: 3600205306 | C23: VTR 4 RODAS | D23: OPERACIONAL | E23: CHEVROLET | F23: S10 | G23: 2014 | H23: SEDE BPMA | I23: {=IFERROR(XLOOKUP(A23,RESPOSTAS!B:B,RESPOSTAS!C:C,"",0,-1),"Sem valor")} | J23: {=IFERROR(XLOOKUP(A23,RESPOSTAS!B:B,RESPOSTAS!D:D,"",0,-1),"Sem valor")} -> Descarga | K23: {=IFERROR(XLOOKUP(A23,RESPOSTAS!B:B,RESPOSTAS!E:E,"",0,-1),"Sem valor")} | L23: OVS-9717 | M23: 9BG148FK0EC454197 | N23: NÃO SE APLICA | O23: 3600213122 | P23: 16227D0118 | Q23: INDEFINIDO | R23: INDEFINIDO | S23: INDEFINIDO | U23: {=IFERROR(XLOOKUP(A23,RESPOSTAS!B:B,RESPOSTAS!F:F,"",0,-1),"Sem valor")}
A24: 553216 | B24: 3600205309 | C24: VTR 4 RODAS | D24: OPERACIONAL | E24: CHEVROLET | F24: S10 | G24: 2014 | H24: SEDE BPMA | I24: {=IFERROR(XLOOKUP(A24,RESPOSTAS!B:B,RESPOSTAS!C:C,"",0,-1),"Sem valor")} | J24: {=IFERROR(XLOOKUP(A24,RESPOSTAS!B:B,RESPOSTAS!D:D,"",0,-1),"Sem valor")} -> Disponível | K24: {=IFERROR(XLOOKUP(A24,RESPOSTAS!B:B,RESPOSTAS!E:E,"",0,-1),"Sem valor")} | L24: OVS-9714 | M24: 9BG148FK0EC456726 | N24: NÃO SE APLICA | O24: 3600213133 | P24: 16227D0129 | Q24: INDEFINIDO | R24: INDEFINIDO | S24: INDEFINIDO | U24: {=IFERROR(XLOOKUP(A24,RESPOSTAS!B:B,RESPOSTAS!F:F,"",0,-1),"Sem valor")}
A25: 553204 | B25: 3600205310 | C25: VTR 4 RODAS | D25: OPERACIONAL | E25: CHEVROLET | F25: S10 | G25: 2014 | H25: SEDE BPMA | I25: {=IFERROR(XLOOKUP(A25,RESPOSTAS!B:B,RESPOSTAS!C:C,"",0,-1),"Sem valor")} | J25: {=IFERROR(XLOOKUP(A25,RESPOSTAS!B:B,RESPOSTAS!D:D,"",0,-1),"Sem valor")} -> Indisponível | K25: {=IFERROR(XLOOKUP(A25,RESPOSTAS!B:B,RESPOSTAS!E:E,"",0,-1),"Sem valor")} | L25: OVS-8845 | M25: 9BG148FK0EC456731 | N25: NÃO SE APLICA | O25: 3600213142 | P25: 16227D0138 | Q25: INDEFINIDO | R25: INDEFINIDO | S25: INDEFINIDO | U25: {=IFERROR(XLOOKUP(A25,RESPOSTAS!B:B,RESPOSTAS!F:F,"",0,-1),"Sem valor")}
A26: 553215 | B26: 3600205314 | C26: VTR 4 RODAS | D26: OPERACIONAL | E26: CHEVROLET | F26: S10 | G26: 2014 | H26: SEDE BPMA | I26: {=IFERROR(XLOOKUP(A26,RESPOSTAS!B:B,RESPOSTAS!C:C,"",0,-1),"Sem valor")} | J26: {=IFERROR(XLOOKUP(A26,RESPOSTAS!B:B,RESPOSTAS!D:D,"",0,-1),"Sem valor")} -> Disponível | K26: {=IFERROR(XLOOKUP(A26,RESPOSTAS!B:B,RESPOSTAS!E:E,"",0,-1),"Sem valor")} | L26: OVS-9711 | M26: 9BG148FK0EC456885 | N26: NÃO SE APLICA | O26: NÃO TEM | P26: NÃO SE APLICA | Q26: INDEFINIDO | R26: INDEFINIDO | S26: INDEFINIDO | U26: {=IFERROR(XLOOKUP(A26,RESPOSTAS!B:B,RESPOSTAS!F:F,"",0,-1),"Sem valor")} | V26: Reservado para P2
A27: 553217 | B27: 3600205318 | C27: VTR 4 RODAS | D27: OPERACIONAL | E27: CHEVROLET | F27: S10 | G27: 2014 | H27: SEDE BPMA | I27: {=IFERROR(XLOOKUP(A27,RESPOSTAS!B:B,RESPOSTAS!C:C,"",0,-1),"Sem valor")} | J27: {=IFERROR(XLOOKUP(A27,RESPOSTAS!B:B,RESPOSTAS!D:D,"",0,-1),"Sem valor")} -> Indisponível | K27: {=IFERROR(XLOOKUP(A27,RESPOSTAS!B:B,RESPOSTAS!E:E,"",0,-1),"Sem valor")} | L27: OVS-9721 | M27: 9BG148FK0EC458769 | N27: NÃO SE APLICA | O27: 3600213151 | P27: 16227D0147 | Q27: SVG | R27: INDEFINIDO | S27: INDEFINIDO | U27: {=IFERROR(XLOOKUP(A27,RESPOSTAS!B:B,RESPOSTAS!F:F,"",0,-1),"Sem valor")}
A28: 553252 | B28: 3600205325 | C28: VTR 4 RODAS | D28: OPERACIONAL | E28: CHEVROLET | F28: S10 | G28: 2014 | H28: SEDE BPMA | I28: {=IFERROR(XLOOKUP(A28,RESPOSTAS!B:B,RESPOSTAS!C:C,"",0,-1),"Sem valor")} | J28: {=IFERROR(XLOOKUP(A28,RESPOSTAS!B:B,RESPOSTAS!D:D,"",0,-1),"Sem valor")} -> Indisponível | K28: {=IFERROR(XLOOKUP(A28,RESPOSTAS!B:B,RESPOSTAS!E:E,"",0,-1),"Sem valor")} | L28: OVS-8399 | M28: 9BG148FK0EC454087 | N28: NÃO SE APLICA | O28: 3600213158 | P28: 16227D0154 | Q28: SVG | R28: INDEFINIDO | S28: INDEFINIDO | U28: {=IFERROR(XLOOKUP(A28,RESPOSTAS!B:B,RESPOSTAS!F:F,"",0,-1),"Sem valor")}
A29: 553236 | B29: 3600205339 | C29: VTR 4 RODAS | D29: OPERACIONAL | E29: CHEVROLET | F29: S10 | G29: 2014 | H29: SEDE BPMA | I29: {=IFERROR(XLOOKUP(A29,RESPOSTAS!B:B,RESPOSTAS!C:C,"",0,-1),"Sem valor")} | J29: {=IFERROR(XLOOKUP(A29,RESPOSTAS!B:B,RESPOSTAS!D:D,"",0,-1),"Sem valor")} -> Indisponível | K29: {=IFERROR(XLOOKUP(A29,RESPOSTAS!B:B,RESPOSTAS!E:E,"",0,-1),"Sem valor")} | L29: OVS-8813 | M29: 9BG148FK0EC454842 | N29: NÃO SE APLICA | O29: 3600213119 | P29: 16227D0115 | Q29: INDEFINIDO | R29: INDEFINIDO | S29: INDEFINIDO | U29: {=IFERROR(XLOOKUP(A29,RESPOSTAS!B:B,RESPOSTAS!F:F,"",0,-1),"Sem valor")} | V29: Reservado para P2
A30: 553197 | B30: 3600205353 | C30: VTR 4 RODAS | D30: OPERACIONAL | E30: CHEVROLET | F30: S10 | G30: 2014 | H30: SEDE BPMA | I30: {=IFERROR(XLOOKUP(A30,RESPOSTAS!B:B,RESPOSTAS!C:C,"",0,-1),"Sem valor")} | J30: {=IFERROR(XLOOKUP(A30,RESPOSTAS!B:B,RESPOSTAS!D:D,"",0,-1),"Sem valor")} -> Disponível | K30: {=IFERROR(XLOOKUP(A30,RESPOSTAS!B:B,RESPOSTAS!E:E,"",0,-1),"Sem valor")} | L30: OVS-8840 | M30: 9BG148FK0EC455359 | N30: NÃO SE APLICA | O30: 3600213116 | P30: 16227D0112 | Q30: INDEFINIDO | R30: INDEFINIDO | S30: INDEFINIDO | U30: {=IFERROR(XLOOKUP(A30,RESPOSTAS!B:B,RESPOSTAS!F:F,"",0,-1),"Sem valor")}
A31: 553520 | B31: 3600230995 | C31: VTR 4 RODAS | D31: OPERACIONAL | E31: TOYOTA | F31: HILLUX | G31: 2017 | H31: INDEFINIDO | I31: {=IFERROR(XLOOKUP(A31,RESPOSTAS!B:B,RESPOSTAS!C:C,"",0,-1),"Sem valor")} | J31: {=IFERROR(XLOOKUP(A31,RESPOSTAS!B:B,RESPOSTAS!D:D,"",0,-1),"Sem valor")} -> Disponível | K31: {=IFERROR(XLOOKUP(A31,RESPOSTAS!B:B,RESPOSTAS!E:E,"",0,-1),"Sem valor")} | L31: PBE-5A51 | M31: 8AJHC8CD8H0037119 | N31: 3600231027 | O31: 3600231011 | P31: INDEFINIDO | Q31: INDEFINIDO | R31: INDEFINIDO | S31: INDEFINIDO | U31: {=IFERROR(XLOOKUP(A31,RESPOSTAS!B:B,RESPOSTAS!F:F,"",0,-1),"Sem valor")}
A32: 553556 | B32: 3600242724 | C32: VTR 4 RODAS | D32: OPERACIONAL | E32: TOYOTA | F32: HILLUX | G32: 2017 | H32: INDEFINIDO | I32: {=IFERROR(XLOOKUP(A32,RESPOSTAS!B:B,RESPOSTAS!C:C,"",0,-1),"Sem valor")} | J32: {=IFERROR(XLOOKUP(A32,RESPOSTAS!B:B,RESPOSTAS!D:D,"",0,-1),"Sem valor")} -> Disponível | K32: {=IFERROR(XLOOKUP(A32,RESPOSTAS!B:B,RESPOSTAS!E:E,"",0,-1),"Sem valor")} | L32: PBI-8727 | M32: 8AJHC8CD0H0037261 | N32: 3600242774 | O32: 3600242749 | P32: INDEFINIDO | Q32: INDEFINIDO | R32: INDEFINIDO | S32: INDEFINIDO | U32: {=IFERROR(XLOOKUP(A32,RESPOSTAS!B:B,RESPOSTAS!F:F,"",0,-1),"Sem valor")}
A33: 77125 | B33: 3600261405 | C33: EMBARCAÇÃO | D33: OPERACIONAL | E33: SEA-DOO | F33: Moto aquática GTX 170 | G33: 2020/2021 | H33: LACUSTRE | I33: {=IFERROR(XLOOKUP(A33,RESPOSTAS!B:B,RESPOSTAS!C:C,"",0,-1),"Sem valor")} | J33: {=IFERROR(XLOOKUP(A33,RESPOSTAS!B:B,RESPOSTAS!D:D,"",0,-1),"Sem valor")} -> Sem informações | K33: {=IFERROR(XLOOKUP(A33,RESPOSTAS!B:B,RESPOSTAS!E:E,"",0,-1),"Sem valor")} | L33: JET-7125 | M33: YDV06125H021 | N33: NÃO SE APLICA | O33: NÃO TEM | P33: NÃO SE APLICA | Q33: LACUSTRE | R33: NÃO SE APLICA | S33: NÃO SE APLICA | U33: {=IFERROR(XLOOKUP(A33,RESPOSTAS!B:B,RESPOSTAS!F:F,"",0,-1),"Sem valor")} | V33: JET IX (PLOTADO 09)
A34: 77124 | B34: 3600261406 | C34: EMBARCAÇÃO | D34: OPERACIONAL | E34: SEA-DOO | F34: Moto aquática GTX 171 | G34: 2020/2021 | H34: LACUSTRE | I34: {=IFERROR(XLOOKUP(A34,RESPOSTAS!B:B,RESPOSTAS!C:C,"",0,-1),"Sem valor")} | J34: {=IFERROR(XLOOKUP(A34,RESPOSTAS!B:B,RESPOSTAS!D:D,"",0,-1),"Sem valor")} -> Sem informações | K34: {=IFERROR(XLOOKUP(A34,RESPOSTAS!B:B,RESPOSTAS!E:E,"",0,-1),"Sem valor")} | L34: JET-7724 | M34: YDV05016H021 | N34: NÃO SE APLICA | O34: NÃO TEM | P34: NÃO SE APLICA | Q34: LACUSTRE | R34: NÃO SE APLICA | S34: NÃO SE APLICA | U34: {=IFERROR(XLOOKUP(A34,RESPOSTAS!B:B,RESPOSTAS!F:F,"",0,-1),"Sem valor")} | V34: JET X (PLOTADO 10)
A35: 77126 | B35: 3600261409 | C35: EMBARCAÇÃO | D35: OPERACIONAL | E35: TCN DO BRASIL | F35: KARUANÃ | G35: INDEFINIDO | H35: LACUSTRE | I35: {=IFERROR(XLOOKUP(A35,RESPOSTAS!B:B,RESPOSTAS!C:C,"",0,-1),"Sem valor")} | J35: {=IFERROR(XLOOKUP(A35,RESPOSTAS!B:B,RESPOSTAS!D:D,"",0,-1),"Sem valor")} -> Sem informações | K35: {=IFERROR(XLOOKUP(A35,RESPOSTAS!B:B,RESPOSTAS!E:E,"",0,-1),"Sem valor")} | L35: LAC-0326 | M35: NÃO TEM | N35: NÃO SE APLICA | O35: NÃO TEM | P35: NÃO SE APLICA | Q35: LACUSTRE | R35: NÃO SE APLICA | S35: NÃO SE APLICA | U35: {=IFERROR(XLOOKUP(A35,RESPOSTAS!B:B,RESPOSTAS!F:F,"",0,-1),"Sem valor")} | V35: Lacustre 03
A36: 77127 | B36: 3600261410 | C36: EMBARCAÇÃO | D36: OPERACIONAL | E36: TCN DO BRASIL | F36: KARUANÃ | G36: INDEFINIDO | H36: LACUSTRE | I36: {=IFERROR(XLOOKUP(A36,RESPOSTAS!B:B,RESPOSTAS!C:C,"",0,-1),"Sem valor")} | J36: {=IFERROR(XLOOKUP(A36,RESPOSTAS!B:B,RESPOSTAS!D:D,"",0,-1),"Sem valor")} -> Sem informações | K36: {=IFERROR(XLOOKUP(A36,RESPOSTAS!B:B,RESPOSTAS!E:E,"",0,-1),"Sem valor")} | L36: NÃO TEM | M36: NÃO TEM | N36: NÃO SE APLICA | O36: NÃO TEM | P36: NÃO SE APLICA | Q36: LACUSTRE | R36: NÃO SE APLICA | S36: NÃO SE APLICA | U36: {=IFERROR(XLOOKUP(A36,RESPOSTAS!B:B,RESPOSTAS!F:F,"",0,-1),"Sem valor")} | V36: Lacustre 04
A37: 553959 | B37: 3600247624 | C37: VTR 4 RODAS | D37: OPERACIONAL | E37: MITSUBISHI | F37: ASX | G37: 2018/2019 | H37: SEDE BPMA | I37: {=IFERROR(XLOOKUP(A37,RESPOSTAS!B:B,RESPOSTAS!C:C,"",0,-1),"Sem valor")} | J37: {=IFERROR(XLOOKUP(A37,RESPOSTAS!B:B,RESPOSTAS!D:D,"",0,-1),"Sem valor")} -> Disponível | K37: {=IFERROR(XLOOKUP(A37,RESPOSTAS!B:B,RESPOSTAS!E:E,"",0,-1),"Sem valor")} | L37: PBN 7383 | M37: 93XFTGA2WKCJ42565 | N37: 3600247672 | O37: 3600212886 | P37: 16227A0694 | Q37: SVG/FISCAL | R37: INDEFINIDO | S37: INDEFINIDO | U37: {=IFERROR(XLOOKUP(A37,RESPOSTAS!B:B,RESPOSTAS!F:F,"",0,-1),"Sem valor")}
A38: 11943 | B38: 3600251179 | C38: VTR 4 RODAS | D38: ADMINISTRATIVO | E38: RENAULT | F38: Kwid Intense 1.0L | G38: 2019 | H38: 11º BPM | I38: {=IFERROR(XLOOKUP(A38,RESPOSTAS!B:B,RESPOSTAS!C:C,"",0,-1),"Sem valor")} | J38: {=IFERROR(XLOOKUP(A38,RESPOSTAS!B:B,RESPOSTAS!D:D,"",0,-1),"Sem valor")} -> Disponível | K38: {=IFERROR(XLOOKUP(A38,RESPOSTAS!B:B,RESPOSTAS!E:E,"",0,-1),"Sem valor")} | L38: PBR-6764 | M38: 93YRBB004KJ838462 | N38: NÃO SE APLICA | O38: NÃO TEM | P38: NÃO SE APLICA | Q38: PREALG | R38: INDEFINIDO | S38: INDEFINIDO | U38: {=IFERROR(XLOOKUP(A38,RESPOSTAS!B:B,RESPOSTAS!F:F,"",0,-1),"Sem valor")}
A39: 559384 | B39: 3600273208 | C39: VTR 4 RODAS | D39: VELADO | E39: FORD | F39: KA FREESTYLE 1.5 AT | G39: 2020/2021 | H39: SEDE BPMA | I39: {=IFERROR(XLOOKUP(A39,RESPOSTAS!B:B,RESPOSTAS!C:C,"",0,-1),"Sem valor")} | J39: {=IFERROR(XLOOKUP(A39,RESPOSTAS!B:B,RESPOSTAS!D:D,"",0,-1),"Sem valor")} -> Indisponível | K39: {=IFERROR(XLOOKUP(A39,RESPOSTAS!B:B,RESPOSTAS!E:E,"",0,-1),"Sem valor")} | L39: REN3A47 | M39: 9BFZH55S9M8092763 | N39: NÃO SE APLICA | O39: 3600212646 | P39: 16227A0454 | Q39: INDEFINIDO | R39: INDEFINIDO | S39: INDEFINIDO | U39: {=IFERROR(XLOOKUP(A39,RESPOSTAS!B:B,RESPOSTAS!F:F,"",0,-1),"Sem valor")}
A40: 554332 | B40: 3600284538 | C40: VTR 4 RODAS | D40: OPERACIONAL | E40: CHEVROLET | F40: Trailblazer LT 4x4 | G40: 2023 | H40: SEDE BPMA | I40: {=IFERROR(XLOOKUP(A40,RESPOSTAS!B:B,RESPOSTAS!C:C,"",0,-1),"Sem valor")} | J40: {=IFERROR(XLOOKUP(A40,RESPOSTAS!B:B,RESPOSTAS!D:D,"",0,-1),"Sem valor")} -> Indisponível | K40: {=IFERROR(XLOOKUP(A40,RESPOSTAS!B:B,RESPOSTAS!E:E,"",0,-1),"Sem valor")} | L40: SGT6F28 | M40: 9BG156FK0PC444009 | N40: 3600284606 | O40: 3600211907 | P40: 16225D0265 | Q40: GTA | R40: INDEFINIDO | S40: INDEFINIDO | U40: {=IFERROR(XLOOKUP(A40,RESPOSTAS!B:B,RESPOSTAS!F:F,"",0,-1),"Sem valor")}
...

Sheet MODELO RELATÓRIO MENSAL SEI
A1: UPM | B1: QUANTIDADE | C1: TIPO | D1: MARCA | E1: MODELO | F1: PREFIXO | G1: PLACA | H1: PLACA VINCULADA | I1: ANO FABRICAÇÃO | J1: TOMBAMENTO | K1: TOMBAMENTO RÁDIO | L1: TOMBAMENTO KIT SINALIZADOR | M1: KM ATUAL | N1: SITUAÇÃO | O1: LOCAL QUE A VIATURA SE ENCONTRA | P1: INFORMAÇÕES COMPLEMENTARES
A2: BPMA | B2: 1 | C2: {=IFERROR(XLOOKUP(F2, 'MAPA DE VTR BPMA'!A:A,'MAPA DE VTR BPMA'!D:D,"",0,-1),"Sem valor")} -> ADMINISTRATIVO | D2: {=IFERROR(XLOOKUP(F2, 'MAPA DE VTR BPMA'!A:A,'MAPA DE VTR BPMA'!E:E,"",0,-1),"Sem valor")} -> AGRITECH | E2: {=IFERROR(XLOOKUP(F2, 'MAPA DE VTR BPMA'!A:A,'MAPA DE VTR BPMA'!F:F,"",0,-1),"Sem valor")} -> 1175 | F2: 33183 | G2: {=IFERROR(XLOOKUP(F2, 'MAPA DE VTR BPMA'!A:A,'MAPA DE VTR BPMA'!L:L,"",0,-1),"Sem valor")} -> JKA4548 | H2: - | I2: {=IFERROR(XLOOKUP(F2, 'MAPA DE VTR BPMA'!A:A,'MAPA DE VTR BPMA'!G:G,"",0,-1),"Sem valor")} -> 2010 | J2: {=IFERROR(XLOOKUP(F2, 'MAPA DE VTR BPMA'!A:A,'MAPA DE VTR BPMA'!B:B,"",0,-1),"Sem valor")} -> 3600150586 | K2: {=IFERROR(XLOOKUP($F2, 'MAPA DE VTR BPMA'!A:A,'MAPA DE VTR BPMA'!O:O,"",0,-1),"Sem valor")} -> NÃO TEM | L2: {=IFERROR(XLOOKUP($F2, 'MAPA DE VTR BPMA'!A:A,'MAPA DE VTR BPMA'!N:N,"",0,-1),"Sem valor")} -> NÃO SE APLICA | M2: {=IFERROR(XLOOKUP($F2, 'MAPA DE VTR BPMA'!A:A,'MAPA DE VTR BPMA'!I:I,"",0,-1),"Sem valor")} | N2: {=IFERROR(XLOOKUP($F2, 'MAPA DE VTR BPMA'!A:A,'MAPA DE VTR BPMA'!J:J,"",0,-1),"Sem valor")} -> Disponível | O2: {=IFERROR(XLOOKUP($F2, 'MAPA DE VTR BPMA'!A:A,'MAPA DE VTR BPMA'!H:H,"",0,-1),"Sem valor")} -> LACUSTRE
A3: Total de Tratores | B3: =B2 -> 1
A4: BPMA | B4: 1 | C4: {=IFERROR(XLOOKUP(F4, 'MAPA DE VTR BPMA'!A:A,'MAPA DE VTR BPMA'!D:D,"",0,-1),"Sem valor")} -> OPERACIONAL | D4: {=IFERROR(XLOOKUP(F4, 'MAPA DE VTR BPMA'!A:A,'MAPA DE VTR BPMA'!E:E,"",0,-1),"Sem valor")} -> CHEVROLET | E4: {=IFERROR(XLOOKUP(F4, 'MAPA DE VTR BPMA'!A:A,'MAPA DE VTR BPMA'!F:F,"",0,-1),"Sem valor")} -> S10 | F4: 553197 | G4: {=IFERROR(XLOOKUP(F4, 'MAPA DE VTR BPMA'!A:A,'MAPA DE VTR BPMA'!L:L,"",0,-1),"Sem valor")} -> OVS-8840 | H4: - | I4: {=IFERROR(XLOOKUP(F4, 'MAPA DE VTR BPMA'!A:A,'MAPA DE VTR BPMA'!G:G,"",0,-1),"Sem valor")} -> 2014 | J4: {=IFERROR(XLOOKUP(F4, 'MAPA DE VTR BPMA'!A:A,'MAPA DE VTR BPMA'!B:B,"",0,-1),"Sem valor")} -> 3600205353 | K4: {=IFERROR(XLOOKUP($F4, 'MAPA DE VTR BPMA'!A:A,'MAPA DE VTR BPMA'!O:O,"",0,-1),"Sem valor")} -> 3600213116 | L4: {=IFERROR(XLOOKUP($F4, 'MAPA DE VTR BPMA'!A:A,'MAPA DE VTR BPMA'!N:N,"",0,-1),"Sem valor")} -> NÃO SE APLICA | M4: {=IFERROR(XLOOKUP($F4, 'MAPA DE VTR BPMA'!A:A,'MAPA DE VTR BPMA'!I:I,"",0,-1),"Sem valor")} | N4: {=IFERROR(XLOOKUP($F4, 'MAPA DE VTR BPMA'!A:A,'MAPA DE VTR BPMA'!J:J,"",0,-1),"Sem valor")} -> Disponível | O4: {=IFERROR(XLOOKUP($F4, 'MAPA DE VTR BPMA'!A:A,'MAPA DE VTR BPMA'!H:H,"",0,-1),"Sem valor")} -> SEDE BPMA
A5: BPMA | B5: 2 | C5: {=IFERROR(XLOOKUP(F5, 'MAPA DE VTR BPMA'!A:A,'MAPA DE VTR BPMA'!D:D,"",0,-1),"Sem valor")} -> OPERACIONAL | D5: {=IFERROR(XLOOKUP(F5, 'MAPA DE VTR BPMA'!A:A,'MAPA DE VTR BPMA'!E:E,"",0,-1),"Sem valor")} -> CHEVROLET | E5: {=IFERROR(XLOOKUP(F5, 'MAPA DE VTR BPMA'!A:A,'MAPA DE VTR BPMA'!F:F,"",0,-1),"Sem valor")} -> S10 | F5: 553200 | G5: {=IFERROR(XLOOKUP(F5, 'MAPA DE VTR BPMA'!A:A,'MAPA DE VTR BPMA'!L:L,"",0,-1),"Sem valor")} -> OVS-9717 | H5: - | I5: {=IFERROR(XLOOKUP(F5, 'MAPA DE VTR BPMA'!A:A,'MAPA DE VTR BPMA'!G:G,"",0,-1),"Sem valor")} -> 2014 | J5: {=IFERROR(XLOOKUP(F5, 'MAPA DE VTR BPMA'!A:A,'MAPA DE VTR BPMA'!B:B,"",0,-1),"Sem valor")} -> 3600205306 | K5: {=IFERROR(XLOOKUP($F5, 'MAPA DE VTR BPMA'!A:A,'MAPA DE VTR BPMA'!O:O,"",0,-1),"Sem valor")} -> 3600213122 | L5: {=IFERROR(XLOOKUP($F5, 'MAPA DE VTR BPMA'!A:A,'MAPA DE VTR BPMA'!N:N,"",0,-1),"Sem valor")} -> NÃO SE APLICA | M5: {=IFERROR(XLOOKUP($F5, 'MAPA DE VTR BPMA'!A:A,'MAPA DE VTR BPMA'!I:I,"",0,-1),"Sem valor")} | N5: {=IFERROR(XLOOKUP($F5, 'MAPA DE VTR BPMA'!A:A,'MAPA DE VTR BPMA'!J:J,"",0,-1),"Sem valor")} -> Descarga | O5: {=IFERROR(XLOOKUP($F5, 'MAPA DE VTR BPMA'!A:A,'MAPA DE VTR BPMA'!H:H,"",0,-1),"Sem valor")} -> SEDE BPMA
A6: BPMA | B6: 3 | C6: {=IFERROR(XLOOKUP(F6, 'MAPA DE VTR BPMA'!A:A,'MAPA DE VTR BPMA'!D:D,"",0,-1),"Sem valor")} -> OPERACIONAL | D6: {=IFERROR(XLOOKUP(F6, 'MAPA DE VTR BPMA'!A:A,'MAPA DE VTR BPMA'!E:E,"",0,-1),"Sem valor")} -> CHEVROLET | E6: {=IFERROR(XLOOKUP(F6, 'MAPA DE VTR BPMA'!A:A,'MAPA DE VTR BPMA'!F:F,"",0,-1),"Sem valor")} -> S10 | F6: 553204 | G6: {=IFERROR(XLOOKUP(F6, 'MAPA DE VTR BPMA'!A:A,'MAPA DE VTR BPMA'!L:L,"",0,-1),"Sem valor")} -> OVS-8845 | H6: - | I6: {=IFERROR(XLOOKUP(F6, 'MAPA DE VTR BPMA'!A:A,'MAPA DE VTR BPMA'!G:G,"",0,-1),"Sem valor")} -> 2014 | J6: {=IFERROR(XLOOKUP(F6, 'MAPA DE VTR BPMA'!A:A,'MAPA DE VTR BPMA'!B:B,"",0,-1),"Sem valor")} -> 3600205310 | K6: {=IFERROR(XLOOKUP($F6, 'MAPA DE VTR BPMA'!A:A,'MAPA DE VTR BPMA'!O:O,"",0,-1),"Sem valor")} -> 3600213142 | L6: {=IFERROR(XLOOKUP($F6, 'MAPA DE VTR BPMA'!A:A,'MAPA DE VTR BPMA'!N:N,"",0,-1),"Sem valor")} -> NÃO SE APLICA | M6: {=IFERROR(XLOOKUP($F6, 'MAPA DE VTR BPMA'!A:A,'MAPA DE VTR BPMA'!I:I,"",0,-1),"Sem valor")} | N6: {=IFERROR(XLOOKUP($F6, 'MAPA DE VTR BPMA'!A:A,'MAPA DE VTR BPMA'!J:J,"",0,-1),"Sem valor")} -> Indisponível | O6: {=IFERROR(XLOOKUP($F6, 'MAPA DE VTR BPMA'!A:A,'MAPA DE VTR BPMA'!H:H,"",0,-1),"Sem valor")} -> SEDE BPMA
A7: BPMA | B7: 4 | C7: {=IFERROR(XLOOKUP(F7, 'MAPA DE VTR BPMA'!A:A,'MAPA DE VTR BPMA'!D:D,"",0,-1),"Sem valor")} -> OPERACIONAL | D7: {=IFERROR(XLOOKUP(F7, 'MAPA DE VTR BPMA'!A:A,'MAPA DE VTR BPMA'!E:E,"",0,-1),"Sem valor")} -> CHEVROLET | E7: {=IFERROR(XLOOKUP(F7, 'MAPA DE VTR BPMA'!A:A,'MAPA DE VTR BPMA'!F:F,"",0,-1),"Sem valor")} -> S10 | F7: 553206 | G7: {=IFERROR(XLOOKUP(F7, 'MAPA DE VTR BPMA'!A:A,'MAPA DE VTR BPMA'!L:L,"",0,-1),"Sem valor")} -> OVS-9707 | H7: - | I7: {=IFERROR(XLOOKUP(F7, 'MAPA DE VTR BPMA'!A:A,'MAPA DE VTR BPMA'!G:G,"",0,-1),"Sem valor")} -> 2014 | J7: {=IFERROR(XLOOKUP(F7, 'MAPA DE VTR BPMA'!A:A,'MAPA DE VTR BPMA'!B:B,"",0,-1),"Sem valor")} -> 3600205300 | K7: {=IFERROR(XLOOKUP($F7, 'MAPA DE VTR BPMA'!A:A,'MAPA DE VTR BPMA'!O:O,"",0,-1),"Sem valor")} -> NÃO TEM | L7: {=IFERROR(XLOOKUP($F7, 'MAPA DE VTR BPMA'!A:A,'MAPA DE VTR BPMA'!N:N,"",0,-1),"Sem valor")} -> NÃO SE APLICA | M7: {=IFERROR(XLOOKUP($F7, 'MAPA DE VTR BPMA'!A:A,'MAPA DE VTR BPMA'!I:I,"",0,-1),"Sem valor")} | N7: {=IFERROR(XLOOKUP($F7, 'MAPA DE VTR BPMA'!A:A,'MAPA DE VTR BPMA'!J:J,"",0,-1),"Sem valor")} -> Disponível | O7: {=IFERROR(XLOOKUP($F7, 'MAPA DE VTR BPMA'!A:A,'MAPA DE VTR BPMA'!H:H,"",0,-1),"Sem valor")} -> SEDE BPMA
A8: BPMA | B8: 5 | C8: {=IFERROR(XLOOKUP(F8, 'MAPA DE VTR BPMA'!A:A,'MAPA DE VTR BPMA'!D:D,"",0,-1),"Sem valor")} -> OPERACIONAL | D8: {=IFERROR(XLOOKUP(F8, 'MAPA DE VTR BPMA'!A:A,'MAPA DE VTR BPMA'!E:E,"",0,-1),"Sem valor")} -> CHEVROLET | E8: {=IFERROR(XLOOKUP(F8, 'MAPA DE VTR BPMA'!A:A,'MAPA DE VTR BPMA'!F:F,"",0,-1),"Sem valor")} -> S10 | F8: 553210 | G8: {=IFERROR(XLOOKUP(F8, 'MAPA DE VTR BPMA'!A:A,'MAPA DE VTR BPMA'!L:L,"",0,-1),"Sem valor")} -> OVS-9715 | H8: - | I8: {=IFERROR(XLOOKUP(F8, 'MAPA DE VTR BPMA'!A:A,'MAPA DE VTR BPMA'!G:G,"",0,-1),"Sem valor")} -> 2014 | J8: {=IFERROR(XLOOKUP(F8, 'MAPA DE VTR BPMA'!A:A,'MAPA DE VTR BPMA'!B:B,"",0,-1),"Sem valor")} -> 3600205301 | K8: {=IFERROR(XLOOKUP($F8, 'MAPA DE VTR BPMA'!A:A,'MAPA DE VTR BPMA'!O:O,"",0,-1),"Sem valor")} -> NÃO TEM | L8: {=IFERROR(XLOOKUP($F8, 'MAPA DE VTR BPMA'!A:A,'MAPA DE VTR BPMA'!N:N,"",0,-1),"Sem valor")} -> NÃO SE APLICA | M8: {=IFERROR(XLOOKUP($F8, 'MAPA DE VTR BPMA'!A:A,'MAPA DE VTR BPMA'!I:I,"",0,-1),"Sem valor")} | N8: {=IFERROR(XLOOKUP($F8, 'MAPA DE VTR BPMA'!A:A,'MAPA DE VTR BPMA'!J:J,"",0,-1),"Sem valor")} -> Disponível | O8: {=IFERROR(XLOOKUP($F8, 'MAPA DE VTR BPMA'!A:A,'MAPA DE VTR BPMA'!H:H,"",0,-1),"Sem valor")} -> SEDE BPMA
A9: BPMA | B9: 6 | C9: {=IFERROR(XLOOKUP(F9, 'MAPA DE VTR BPMA'!A:A,'MAPA DE VTR BPMA'!D:D,"",0,-1),"Sem valor")} -> OPERACIONAL | D9: {=IFERROR(XLOOKUP(F9, 'MAPA DE VTR BPMA'!A:A,'MAPA DE VTR BPMA'!E:E,"",0,-1),"Sem valor")} -> CHEVROLET | E9: {=IFERROR(XLOOKUP(F9, 'MAPA DE VTR BPMA'!A:A,'MAPA DE VTR BPMA'!F:F,"",0,-1),"Sem valor")} -> S10 | F9: 553215 | G9: {=IFERROR(XLOOKUP(F9, 'MAPA DE VTR BPMA'!A:A,'MAPA DE VTR BPMA'!L:L,"",0,-1),"Sem valor")} -> OVS-9711 | H9: - | I9: {=IFERROR(XLOOKUP(F9, 'MAPA DE VTR BPMA'!A:A,'MAPA DE VTR BPMA'!G:G,"",0,-1),"Sem valor")} -> 2014 | J9: {=IFERROR(XLOOKUP(F9, 'MAPA DE VTR BPMA'!A:A,'MAPA DE VTR BPMA'!B:B,"",0,-1),"Sem valor")} -> 3600205314 | K9: {=IFERROR(XLOOKUP($F9, 'MAPA DE VTR BPMA'!A:A,'MAPA DE VTR BPMA'!O:O,"",0,-1),"Sem valor")} -> NÃO TEM | L9: {=IFERROR(XLOOKUP($F9, 'MAPA DE VTR BPMA'!A:A,'MAPA DE VTR BPMA'!N:N,"",0,-1),"Sem valor")} -> NÃO SE APLICA | M9: {=IFERROR(XLOOKUP($F9, 'MAPA DE VTR BPMA'!A:A,'MAPA DE VTR BPMA'!I:I,"",0,-1),"Sem valor")} | N9: {=IFERROR(XLOOKUP($F9, 'MAPA DE VTR BPMA'!A:A,'MAPA DE VTR BPMA'!J:J,"",0,-1),"Sem valor")} -> Disponível | O9: {=IFERROR(XLOOKUP($F9, 'MAPA DE VTR BPMA'!A:A,'MAPA DE VTR BPMA'!H:H,"",0,-1),"Sem valor")} -> SEDE BPMA
A10: BPMA | B10: 7 | C10: {=IFERROR(XLOOKUP(F10, 'MAPA DE VTR BPMA'!A:A,'MAPA DE VTR BPMA'!D:D,"",0,-1),"Sem valor")} -> OPERACIONAL | D10: {=IFERROR(XLOOKUP(F10, 'MAPA DE VTR BPMA'!A:A,'MAPA DE VTR BPMA'!E:E,"",0,-1),"Sem valor")} -> CHEVROLET | E10: {=IFERROR(XLOOKUP(F10, 'MAPA DE VTR BPMA'!A:A,'MAPA DE VTR BPMA'!F:F,"",0,-1),"Sem valor")} -> S10 | F10: 553216 | G10: {=IFERROR(XLOOKUP(F10, 'MAPA DE VTR BPMA'!A:A,'MAPA DE VTR BPMA'!L:L,"",0,-1),"Sem valor")} -> OVS-9714 | H10: - | I10: {=IFERROR(XLOOKUP(F10, 'MAPA DE VTR BPMA'!A:A,'MAPA DE VTR BPMA'!G:G,"",0,-1),"Sem valor")} -> 2014 | J10: {=IFERROR(XLOOKUP(F10, 'MAPA DE VTR BPMA'!A:A,'MAPA DE VTR BPMA'!B:B,"",0,-1),"Sem valor")} -> 3600205309 | K10: {=IFERROR(XLOOKUP($F10, 'MAPA DE VTR BPMA'!A:A,'MAPA DE VTR BPMA'!O:O,"",0,-1),"Sem valor")} -> 3600213133 | L10: {=IFERROR(XLOOKUP($F10, 'MAPA DE VTR BPMA'!A:A,'MAPA DE VTR BPMA'!N:N,"",0,-1),"Sem valor")} -> NÃO SE APLICA | M10: {=IFERROR(XLOOKUP($F10, 'MAPA DE VTR BPMA'!A:A,'MAPA DE VTR BPMA'!I:I,"",0,-1),"Sem valor")} | N10: {=IFERROR(XLOOKUP($F10, 'MAPA DE VTR BPMA'!A:A,'MAPA DE VTR BPMA'!J:J,"",0,-1),"Sem valor")} -> Disponível | O10: {=IFERROR(XLOOKUP($F10, 'MAPA DE VTR BPMA'!A:A,'MAPA DE VTR BPMA'!H:H,"",0,-1),"Sem valor")} -> SEDE BPMA
A11: BPMA | B11: 8 | C11: {=IFERROR(XLOOKUP(F11, 'MAPA DE VTR BPMA'!A:A,'MAPA DE VTR BPMA'!D:D,"",0,-1),"Sem valor")} -> OPERACIONAL | D11: {=IFERROR(XLOOKUP(F11, 'MAPA DE VTR BPMA'!A:A,'MAPA DE VTR BPMA'!E:E,"",0,-1),"Sem valor")} -> CHEVROLET | E11: {=IFERROR(XLOOKUP(F11, 'MAPA DE VTR BPMA'!A:A,'MAPA DE VTR BPMA'!F:F,"",0,-1),"Sem valor")} -> S10 | F11: 553217 | G11: {=IFERROR(XLOOKUP(F11, 'MAPA DE VTR BPMA'!A:A,'MAPA DE VTR BPMA'!L:L,"",0,-1),"Sem valor")} -> OVS-9721 | H11: - | I11: {=IFERROR(XLOOKUP(F11, 'MAPA DE VTR BPMA'!A:A,'MAPA DE VTR BPMA'!G:G,"",0,-1),"Sem valor")} -> 2014 | J11: {=IFERROR(XLOOKUP(F11, 'MAPA DE VTR BPMA'!A:A,'MAPA DE VTR BPMA'!B:B,"",0,-1),"Sem valor")} -> 3600205318 | K11: {=IFERROR(XLOOKUP($F11, 'MAPA DE VTR BPMA'!A:A,'MAPA DE VTR BPMA'!O:O,"",0,-1),"Sem valor")} -> 3600213151 | L11: {=IFERROR(XLOOKUP($F11, 'MAPA DE VTR BPMA'!A:A,'MAPA DE VTR BPMA'!N:N,"",0,-1),"Sem valor")} -> NÃO SE APLICA | M11: {=IFERROR(XLOOKUP($F11, 'MAPA DE VTR BPMA'!A:A,'MAPA DE VTR BPMA'!I:I,"",0,-1),"Sem valor")} | N11: {=IFERROR(XLOOKUP($F11, 'MAPA DE VTR BPMA'!A:A,'MAPA DE VTR BPMA'!J:J,"",0,-1),"Sem valor")} -> Indisponível | O11: {=IFERROR(XLOOKUP($F11, 'MAPA DE VTR BPMA'!A:A,'MAPA DE VTR BPMA'!H:H,"",0,-1),"Sem valor")} -> SEDE BPMA
A12: BPMA | B12: 9 | C12: {=IFERROR(XLOOKUP(F12, 'MAPA DE VTR BPMA'!A:A,'MAPA DE VTR BPMA'!D:D,"",0,-1),"Sem valor")} -> OPERACIONAL | D12: {=IFERROR(XLOOKUP(F12, 'MAPA DE VTR BPMA'!A:A,'MAPA DE VTR BPMA'!E:E,"",0,-1),"Sem valor")} -> CHEVROLET | E12: {=IFERROR(XLOOKUP(F12, 'MAPA DE VTR BPMA'!A:A,'MAPA DE VTR BPMA'!F:F,"",0,-1),"Sem valor")} -> S10 | F12: 553218 | G12: {=IFERROR(XLOOKUP(F12, 'MAPA DE VTR BPMA'!A:A,'MAPA DE VTR BPMA'!L:L,"",0,-1),"Sem valor")} -> OVS-8850 | H12: - | I12: {=IFERROR(XLOOKUP(F12, 'MAPA DE VTR BPMA'!A:A,'MAPA DE VTR BPMA'!G:G,"",0,-1),"Sem valor")} -> 2014 | J12: {=IFERROR(XLOOKUP(F12, 'MAPA DE VTR BPMA'!A:A,'MAPA DE VTR BPMA'!B:B,"",0,-1),"Sem valor")} -> 3600205299 | K12: {=IFERROR(XLOOKUP($F12, 'MAPA DE VTR BPMA'!A:A,'MAPA DE VTR BPMA'!O:O,"",0,-1),"Sem valor")} -> NÃO TEM | L12: {=IFERROR(XLOOKUP($F12, 'MAPA DE VTR BPMA'!A:A,'MAPA DE VTR BPMA'!N:N,"",0,-1),"Sem valor")} -> NÃO SE APLICA | M12: {=IFERROR(XLOOKUP($F12, 'MAPA DE VTR BPMA'!A:A,'MAPA DE VTR BPMA'!I:I,"",0,-1),"Sem valor")} | N12: {=IFERROR(XLOOKUP($F12, 'MAPA DE VTR BPMA'!A:A,'MAPA DE VTR BPMA'!J:J,"",0,-1),"Sem valor")} -> Descarga | O12: {=IFERROR(XLOOKUP($F12, 'MAPA DE VTR BPMA'!A:A,'MAPA DE VTR BPMA'!H:H,"",0,-1),"Sem valor")} -> SEDE BPMA
A13: BPMA | B13: 10 | C13: {=IFERROR(XLOOKUP(F13, 'MAPA DE VTR BPMA'!A:A,'MAPA DE VTR BPMA'!D:D,"",0,-1),"Sem valor")} -> OPERACIONAL | D13: {=IFERROR(XLOOKUP(F13, 'MAPA DE VTR BPMA'!A:A,'MAPA DE VTR BPMA'!E:E,"",0,-1),"Sem valor")} -> CHEVROLET | E13: {=IFERROR(XLOOKUP(F13, 'MAPA DE VTR BPMA'!A:A,'MAPA DE VTR BPMA'!F:F,"",0,-1),"Sem valor")} -> S10 | F13: 553236 | G13: {=IFERROR(XLOOKUP(F13, 'MAPA DE VTR BPMA'!A:A,'MAPA DE VTR BPMA'!L:L,"",0,-1),"Sem valor")} -> OVS-8813 | H13: - | I13: {=IFERROR(XLOOKUP(F13, 'MAPA DE VTR BPMA'!A:A,'MAPA DE VTR BPMA'!G:G,"",0,-1),"Sem valor")} -> 2014 | J13: {=IFERROR(XLOOKUP(F13, 'MAPA DE VTR BPMA'!A:A,'MAPA DE VTR BPMA'!B:B,"",0,-1),"Sem valor")} -> 3600205339 | K13: {=IFERROR(XLOOKUP($F13, 'MAPA DE VTR BPMA'!A:A,'MAPA DE VTR BPMA'!O:O,"",0,-1),"Sem valor")} -> 3600213119 | L13: {=IFERROR(XLOOKUP($F13, 'MAPA DE VTR BPMA'!A:A,'MAPA DE VTR BPMA'!N:N,"",0,-1),"Sem valor")} -> NÃO SE APLICA | M13: {=IFERROR(XLOOKUP($F13, 'MAPA DE VTR BPMA'!A:A,'MAPA DE VTR BPMA'!I:I,"",0,-1),"Sem valor")} | N13: {=IFERROR(XLOOKUP($F13, 'MAPA DE VTR BPMA'!A:A,'MAPA DE VTR BPMA'!J:J,"",0,-1),"Sem valor")} -> Indisponível | O13: {=IFERROR(XLOOKUP($F13, 'MAPA DE VTR BPMA'!A:A,'MAPA DE VTR BPMA'!H:H,"",0,-1),"Sem valor")} -> SEDE BPMA
A14: BPMA | B14: 11 | C14: {=IFERROR(XLOOKUP(F14, 'MAPA DE VTR BPMA'!A:A,'MAPA DE VTR BPMA'!D:D,"",0,-1),"Sem valor")} -> OPERACIONAL | D14: {=IFERROR(XLOOKUP(F14, 'MAPA DE VTR BPMA'!A:A,'MAPA DE VTR BPMA'!E:E,"",0,-1),"Sem valor")} -> CHEVROLET | E14: {=IFERROR(XLOOKUP(F14, 'MAPA DE VTR BPMA'!A:A,'MAPA DE VTR BPMA'!F:F,"",0,-1),"Sem valor")} -> S10 | F14: 553252 | G14: {=IFERROR(XLOOKUP(F14, 'MAPA DE VTR BPMA'!A:A,'MAPA DE VTR BPMA'!L:L,"",0,-1),"Sem valor")} -> OVS-8399 | H14: - | I14: {=IFERROR(XLOOKUP(F14, 'MAPA DE VTR BPMA'!A:A,'MAPA DE VTR BPMA'!G:G,"",0,-1),"Sem valor")} -> 2014 | J14: {=IFERROR(XLOOKUP(F14, 'MAPA DE VTR BPMA'!A:A,'MAPA DE VTR BPMA'!B:B,"",0,-1),"Sem valor")} -> 3600205325 | K14: {=IFERROR(XLOOKUP($F14, 'MAPA DE VTR BPMA'!A:A,'MAPA DE VTR BPMA'!O:O,"",0,-1),"Sem valor")} -> 3600213158 | L14: {=IFERROR(XLOOKUP($F14, 'MAPA DE VTR BPMA'!A:A,'MAPA DE VTR BPMA'!N:N,"",0,-1),"Sem valor")} -> NÃO SE APLICA | M14: {=IFERROR(XLOOKUP($F14, 'MAPA DE VTR BPMA'!A:A,'MAPA DE VTR BPMA'!I:I,"",0,-1),"Sem valor")} | N14: {=IFERROR(XLOOKUP($F14, 'MAPA DE VTR BPMA'!A:A,'MAPA DE VTR BPMA'!J:J,"",0,-1),"Sem valor")} -> Indisponível | O14: {=IFERROR(XLOOKUP($F14, 'MAPA DE VTR BPMA'!A:A,'MAPA DE VTR BPMA'!H:H,"",0,-1),"Sem valor")} -> SEDE BPMA
A15: BPMA | B15: 12 | C15: {=IFERROR(XLOOKUP(F15, 'MAPA DE VTR BPMA'!A:A,'MAPA DE VTR BPMA'!D:D,"",0,-1),"Sem valor")} -> OPERACIONAL | D15: {=IFERROR(XLOOKUP(F15, 'MAPA DE VTR BPMA'!A:A,'MAPA DE VTR BPMA'!E:E,"",0,-1),"Sem valor")} -> CHEVROLET | E15: {=IFERROR(XLOOKUP(F15, 'MAPA DE VTR BPMA'!A:A,'MAPA DE VTR BPMA'!F:F,"",0,-1),"Sem valor")} -> S10 LT DD4A | F15: 554496 | G15: {=IFERROR(XLOOKUP(F15, 'MAPA DE VTR BPMA'!A:A,'MAPA DE VTR BPMA'!L:L,"",0,-1),"Sem valor")} -> SGP2C23 | H15: - | I15: {=IFERROR(XLOOKUP(F15, 'MAPA DE VTR BPMA'!A:A,'MAPA DE VTR BPMA'!G:G,"",0,-1),"Sem valor")} -> 2022 | J15: {=IFERROR(XLOOKUP(F15, 'MAPA DE VTR BPMA'!A:A,'MAPA DE VTR BPMA'!B:B,"",0,-1),"Sem valor")} -> 200198856 | K15: {=IFERROR(XLOOKUP($F15, 'MAPA DE VTR BPMA'!A:A,'MAPA DE VTR BPMA'!O:O,"",0,-1),"Sem valor")} -> INDEFINIDO | L15: {=IFERROR(XLOOKUP($F15, 'MAPA DE VTR BPMA'!A:A,'MAPA DE VTR BPMA'!N:N,"",0,-1),"Sem valor")} -> NÃO TEM TOMBAMENTO | M15: {=IFERROR(XLOOKUP($F15, 'MAPA DE VTR BPMA'!A:A,'MAPA DE VTR BPMA'!I:I,"",0,-1),"Sem valor")} | N15: {=IFERROR(XLOOKUP($F15, 'MAPA DE VTR BPMA'!A:A,'MAPA DE VTR BPMA'!J:J,"",0,-1),"Sem valor")} -> Disponível | O15: {=IFERROR(XLOOKUP($F15, 'MAPA DE VTR BPMA'!A:A,'MAPA DE VTR BPMA'!H:H,"",0,-1),"Sem valor")} -> INDEFINIDO
A16: Total de Chevrolet S10 | B16: =B15 -> 12
A17: BPMA | B17: 1 | C17: {=IFERROR(XLOOKUP(F17, 'MAPA DE VTR BPMA'!A:A,'MAPA DE VTR BPMA'!D:D,"",0,-1),"Sem valor")} -> OPERACIONAL | D17: {=IFERROR(XLOOKUP(F17, 'MAPA DE VTR BPMA'!A:A,'MAPA DE VTR BPMA'!E:E,"",0,-1),"Sem valor")} -> FIAT | E17: {=IFERROR(XLOOKUP(F17, 'MAPA DE VTR BPMA'!A:A,'MAPA DE VTR BPMA'!F:F,"",0,-1),"Sem valor")} -> Ducato Multi TA 2.3 | F17: 552942 | G17: {=IFERROR(XLOOKUP(F17, 'MAPA DE VTR BPMA'!A:A,'MAPA DE VTR BPMA'!L:L,"",0,-1),"Sem valor")} -> 18 | H17: - | I17: {=IFERROR(XLOOKUP(F17, 'MAPA DE VTR BPMA'!A:A,'MAPA DE VTR BPMA'!G:G,"",0,-1),"Sem valor")} -> 2012/2013 | J17: {=IFERROR(XLOOKUP(F17, 'MAPA DE VTR BPMA'!A:A,'MAPA DE VTR BPMA'!B:B,"",0,-1),"Sem valor")} -> 3600182242 | K17: {=IFERROR(XLOOKUP($F17, 'MAPA DE VTR BPMA'!A:A,'MAPA DE VTR BPMA'!O:O,"",0,-1),"Sem valor")} -> 3600213121 | L17: {=IFERROR(XLOOKUP($F17, 'MAPA DE VTR BPMA'!A:A,'MAPA DE VTR BPMA'!N:N,"",0,-1),"Sem valor")} -> NÃO SE APLICA | M17: {=IFERROR(XLOOKUP($F17, 'MAPA DE VTR BPMA'!A:A,'MAPA DE VTR BPMA'!I:I,"",0,-1),"Sem valor")} | N17: {=IFERROR(XLOOKUP($F17, 'MAPA DE VTR BPMA'!A:A,'MAPA DE VTR BPMA'!J:J,"",0,-1),"Sem valor")} -> Indisponível | O17: {=IFERROR(XLOOKUP($F17, 'MAPA DE VTR BPMA'!A:A,'MAPA DE VTR BPMA'!H:H,"",0,-1),"Sem valor")} -> PREALG
A18: BPMA | B18: 2 | C18: {=IFERROR(XLOOKUP(F18, 'MAPA DE VTR BPMA'!A:A,'MAPA DE VTR BPMA'!D:D,"",0,-1),"Sem valor")} -> OPERACIONAL | D18: {=IFERROR(XLOOKUP(F18, 'MAPA DE VTR BPMA'!A:A,'MAPA DE VTR BPMA'!E:E,"",0,-1),"Sem valor")} -> MARCOPOLO | E18: {=IFERROR(XLOOKUP(F18, 'MAPA DE VTR BPMA'!A:A,'MAPA DE VTR BPMA'!F:F,"",0,-1),"Sem valor")} -> Volare W9 | F18: 55411 | G18: {=IFERROR(XLOOKUP(F18, 'MAPA DE VTR BPMA'!A:A,'MAPA DE VTR BPMA'!L:L,"",0,-1),"Sem valor")} -> JJU-1689 | H18: - | I18: {=IFERROR(XLOOKUP(F18, 'MAPA DE VTR BPMA'!A:A,'MAPA DE VTR BPMA'!G:G,"",0,-1),"Sem valor")} -> 2012 | J18: {=IFERROR(XLOOKUP(F18, 'MAPA DE VTR BPMA'!A:A,'MAPA DE VTR BPMA'!B:B,"",0,-1),"Sem valor")} -> 3600175200 | K18: {=IFERROR(XLOOKUP($F18, 'MAPA DE VTR BPMA'!A:A,'MAPA DE VTR BPMA'!O:O,"",0,-1),"Sem valor")} -> NÃO TEM | L18: {=IFERROR(XLOOKUP($F18, 'MAPA DE VTR BPMA'!A:A,'MAPA DE VTR BPMA'!N:N,"",0,-1),"Sem valor")} -> NÃO SE APLICA | M18: {=IFERROR(XLOOKUP($F18, 'MAPA DE VTR BPMA'!A:A,'MAPA DE VTR BPMA'!I:I,"",0,-1),"Sem valor")} | N18: {=IFERROR(XLOOKUP($F18, 'MAPA DE VTR BPMA'!A:A,'MAPA DE VTR BPMA'!J:J,"",0,-1),"Sem valor")} -> Disponível | O18: {=IFERROR(XLOOKUP($F18, 'MAPA DE VTR BPMA'!A:A,'MAPA DE VTR BPMA'!H:H,"",0,-1),"Sem valor")} -> LACUSTRE
A19: BPMA | B19: 3 | C19: {=IFERROR(XLOOKUP(F19, 'MAPA DE VTR BPMA'!A:A,'MAPA DE VTR BPMA'!D:D,"",0,-1),"Sem valor")} -> OPERACIONAL | D19: {=IFERROR(XLOOKUP(F19, 'MAPA DE VTR BPMA'!A:A,'MAPA DE VTR BPMA'!E:E,"",0,-1),"Sem valor")} -> MARCOPOLO | E19: {=IFERROR(XLOOKUP(F19, 'MAPA DE VTR BPMA'!A:A,'MAPA DE VTR BPMA'!F:F,"",0,-1),"Sem valor")} -> Volare W9 | F19: 55423 | G19: {=IFERROR(XLOOKUP(F19, 'MAPA DE VTR BPMA'!A:A,'MAPA DE VTR BPMA'!L:L,"",0,-1),"Sem valor")} -> JJU-1799 | H19: - | I19: {=IFERROR(XLOOKUP(F19, 'MAPA DE VTR BPMA'!A:A,'MAPA DE VTR BPMA'!G:G,"",0,-1),"Sem valor")} -> 2012 | J19: {=IFERROR(XLOOKUP(F19, 'MAPA DE VTR BPMA'!A:A,'MAPA DE VTR BPMA'!B:B,"",0,-1),"Sem valor")} -> 3600175206 | K19: {=IFERROR(XLOOKUP($F19, 'MAPA DE VTR BPMA'!A:A,'MAPA DE VTR BPMA'!O:O,"",0,-1),"Sem valor")} -> NÃO TEM | L19: {=IFERROR(XLOOKUP($F19, 'MAPA DE VTR BPMA'!A:A,'MAPA DE VTR BPMA'!N:N,"",0,-1),"Sem valor")} -> NÃO SE APLICA | M19: {=IFERROR(XLOOKUP($F19, 'MAPA DE VTR BPMA'!A:A,'MAPA DE VTR BPMA'!I:I,"",0,-1),"Sem valor")} | N19: {=IFERROR(XLOOKUP($F19, 'MAPA DE VTR BPMA'!A:A,'MAPA DE VTR BPMA'!J:J,"",0,-1),"Sem valor")} -> Disponível | O19: {=IFERROR(XLOOKUP($F19, 'MAPA DE VTR BPMA'!A:A,'MAPA DE VTR BPMA'!H:H,"",0,-1),"Sem valor")} -> SEDE BPMA
A20: BPMA | B20: 4 | C20: {=IFERROR(XLOOKUP(F20, 'MAPA DE VTR BPMA'!A:A,'MAPA DE VTR BPMA'!D:D,"",0,-1),"Sem valor")} -> OPERACIONAL | D20: {=IFERROR(XLOOKUP(F20, 'MAPA DE VTR BPMA'!A:A,'MAPA DE VTR BPMA'!E:E,"",0,-1),"Sem valor")} -> RENAULT | E20: {=IFERROR(XLOOKUP(F20, 'MAPA DE VTR BPMA'!A:A,'MAPA DE VTR BPMA'!F:F,"",0,-1),"Sem valor")} -> Master Vitre Pack luxo | F20: 554285 | G20: {=IFERROR(XLOOKUP(F20, 'MAPA DE VTR BPMA'!A:A,'MAPA DE VTR BPMA'!L:L,"",0,-1),"Sem valor")} -> REQ-8E50 | H20: - | I20: {=IFERROR(XLOOKUP(F20, 'MAPA DE VTR BPMA'!A:A,'MAPA DE VTR BPMA'!G:G,"",0,-1),"Sem valor")} -> 2020/2021 | J20: {=IFERROR(XLOOKUP(F20, 'MAPA DE VTR BPMA'!A:A,'MAPA DE VTR BPMA'!B:B,"",0,-1),"Sem valor")} -> 3600275708 | K20: {=IFERROR(XLOOKUP($F20, 'MAPA DE VTR BPMA'!A:A,'MAPA DE VTR BPMA'!O:O,"",0,-1),"Sem valor")} -> 3600213007 | L20: {=IFERROR(XLOOKUP($F20, 'MAPA DE VTR BPMA'!A:A,'MAPA DE VTR BPMA'!N:N,"",0,-1),"Sem valor")} -> 3600275743 | M20: {=IFERROR(XLOOKUP($F20, 'MAPA DE VTR BPMA'!A:A,'MAPA DE VTR BPMA'!I:I,"",0,-1),"Sem valor")} | N20: {=IFERROR(XLOOKUP($F20, 'MAPA DE VTR BPMA'!A:A,'MAPA DE VTR BPMA'!J:J,"",0,-1),"Sem valor")} -> Disponível | O20: {=IFERROR(XLOOKUP($F20, 'MAPA DE VTR BPMA'!A:A,'MAPA DE VTR BPMA'!H:H,"",0,-1),"Sem valor")} -> PREALG
A21: Total de Ônibus e Vans | B21: =B20 -> 4
A22: BPMA | B22: 1 | C22: {=IFERROR(XLOOKUP(F22, 'MAPA DE VTR BPMA'!A:A,'MAPA DE VTR BPMA'!D:D,"",0,-1),"Sem valor")} -> VELADO | D22: {=IFERROR(XLOOKUP(F22, 'MAPA DE VTR BPMA'!A:A,'MAPA DE VTR BPMA'!E:E,"",0,-1),"Sem valor")} -> FORD | E22: {=IFERROR(XLOOKUP(F22, 'MAPA DE VTR BPMA'!A:A,'MAPA DE VTR BPMA'!F:F,"",0,-1),"Sem valor")} -> KA FREESTYLE 1.5 AT | F22: 559384 | G22: {=IFERROR(XLOOKUP(F22, 'MAPA DE VTR BPMA'!A:A,'MAPA DE VTR BPMA'!L:L,"",0,-1),"Sem valor")} -> REN3A47 | H22: - | I22: {=IFERROR(XLOOKUP(F22, 'MAPA DE VTR BPMA'!A:A,'MAPA DE VTR BPMA'!G:G,"",0,-1),"Sem valor")} -> 2020/2021 | J22: {=IFERROR(XLOOKUP(F22, 'MAPA DE VTR BPMA'!A:A,'MAPA DE VTR BPMA'!B:B,"",0,-1),"Sem valor")} -> 3600273208 | K22: {=IFERROR(XLOOKUP($F22, 'MAPA DE VTR BPMA'!A:A,'MAPA DE VTR BPMA'!O:O,"",0,-1),"Sem valor")} -> 3600212646 | L22: {=IFERROR(XLOOKUP($F22, 'MAPA DE VTR BPMA'!A:A,'MAPA DE VTR BPMA'!N:N,"",0,-1),"Sem valor")} -> NÃO SE APLICA | M22: {=IFERROR(XLOOKUP($F22, 'MAPA DE VTR BPMA'!A:A,'MAPA DE VTR BPMA'!I:I,"",0,-1),"Sem valor")} | N22: {=IFERROR(XLOOKUP($F22, 'MAPA DE VTR BPMA'!A:A,'MAPA DE VTR BPMA'!J:J,"",0,-1),"Sem valor")} -> Indisponível | O22: {=IFERROR(XLOOKUP($F22, 'MAPA DE VTR BPMA'!A:A,'MAPA DE VTR BPMA'!H:H,"",0,-1),"Sem valor")} -> SEDE BPMA
A23: Total de FORD Ka | B23: =B22 -> 1
A24: BPMA | B24: 1 | C24: {=IFERROR(XLOOKUP(F24, 'MAPA DE VTR BPMA'!A:A,'MAPA DE VTR BPMA'!D:D,"",0,-1),"Sem valor")} -> OPERACIONAL | D24: {=IFERROR(XLOOKUP(F24, 'MAPA DE VTR BPMA'!A:A,'MAPA DE VTR BPMA'!E:E,"",0,-1),"Sem valor")} -> CHEVROLET | E24: {=IFERROR(XLOOKUP(F24, 'MAPA DE VTR BPMA'!A:A,'MAPA DE VTR BPMA'!F:F,"",0,-1),"Sem valor")} -> Trailblazer LT 4x4 | F24: 554332 | G24: {=IFERROR(XLOOKUP(F24, 'MAPA DE VTR BPMA'!A:A,'MAPA DE VTR BPMA'!L:L,"",0,-1),"Sem valor")} -> SGT6F28 | H24: - | I24: {=IFERROR(XLOOKUP(F24, 'MAPA DE VTR BPMA'!A:A,'MAPA DE VTR BPMA'!G:G,"",0,-1),"Sem valor")} -> 2023 | J24: {=IFERROR(XLOOKUP(F24, 'MAPA DE VTR BPMA'!A:A,'MAPA DE VTR BPMA'!B:B,"",0,-1),"Sem valor")} -> 3600284538 | K24: {=IFERROR(XLOOKUP($F24, 'MAPA DE VTR BPMA'!A:A,'MAPA DE VTR BPMA'!O:O,"",0,-1),"Sem valor")} -> 3600211907 | L24: {=IFERROR(XLOOKUP($F24, 'MAPA DE VTR BPMA'!A:A,'MAPA DE VTR BPMA'!N:N,"",0,-1),"Sem valor")} -> 3600284606 | M24: {=IFERROR(XLOOKUP($F24, 'MAPA DE VTR BPMA'!A:A,'MAPA DE VTR BPMA'!I:I,"",0,-1),"Sem valor")} | N24: {=IFERROR(XLOOKUP($F24, 'MAPA DE VTR BPMA'!A:A,'MAPA DE VTR BPMA'!J:J,"",0,-1),"Sem valor")} -> Indisponível | O24: {=IFERROR(XLOOKUP($F24, 'MAPA DE VTR BPMA'!A:A,'MAPA DE VTR BPMA'!H:H,"",0,-1),"Sem valor")} -> SEDE BPMA
A25: Total de GM Trailblazer | B25: =B24 -> 1
A26: BPMA | B26: 1 | C26: {=IFERROR(XLOOKUP(F26, 'MAPA DE VTR BPMA'!A:A,'MAPA DE VTR BPMA'!D:D,"",0,-1),"Sem valor")} -> ADMINISTRATIVO | D26: {=IFERROR(XLOOKUP(F26, 'MAPA DE VTR BPMA'!A:A,'MAPA DE VTR BPMA'!E:E,"",0,-1),"Sem valor")} -> HYUNDAI | E26: {=IFERROR(XLOOKUP(F26, 'MAPA DE VTR BPMA'!A:A,'MAPA DE VTR BPMA'!F:F,"",0,-1),"Sem valor")} -> HR 2.5 Turbo | F26: 33548 | G26: {=IFERROR(XLOOKUP(F26, 'MAPA DE VTR BPMA'!A:A,'MAPA DE VTR BPMA'!L:L,"",0,-1),"Sem valor")} -> RER-3C82 | H26: - | I26: {=IFERROR(XLOOKUP(F26, 'MAPA DE VTR BPMA'!A:A,'MAPA DE VTR BPMA'!G:G,"",0,-1),"Sem valor")} -> 2020/2021 | J26: {=IFERROR(XLOOKUP(F26, 'MAPA DE VTR BPMA'!A:A,'MAPA DE VTR BPMA'!B:B,"",0,-1),"Sem valor")} -> 3600275753 | K26: {=IFERROR(XLOOKUP($F26, 'MAPA DE VTR BPMA'!A:A,'MAPA DE VTR BPMA'!O:O,"",0,-1),"Sem valor")} -> 3600212595 | L26: {=IFERROR(XLOOKUP($F26, 'MAPA DE VTR BPMA'!A:A,'MAPA DE VTR BPMA'!N:N,"",0,-1),"Sem valor")} -> 3600275757 | M26: {=IFERROR(XLOOKUP($F26, 'MAPA DE VTR BPMA'!A:A,'MAPA DE VTR BPMA'!I:I,"",0,-1),"Sem valor")} | N26: {=IFERROR(XLOOKUP($F26, 'MAPA DE VTR BPMA'!A:A,'MAPA DE VTR BPMA'!J:J,"",0,-1),"Sem valor")} -> Disponível | O26: {=IFERROR(XLOOKUP($F26, 'MAPA DE VTR BPMA'!A:A,'MAPA DE VTR BPMA'!H:H,"",0,-1),"Sem valor")} -> SEDE BPMA
A27: Total de Caminhões Baú | B27: =B26 -> 1
A28: BPMA | B28: 1 | C28: {=IFERROR(XLOOKUP(F28, 'MAPA DE VTR BPMA'!A:A,'MAPA DE VTR BPMA'!D:D,"",0,-1),"Sem valor")} -> OPERACIONAL | D28: {=IFERROR(XLOOKUP(F28, 'MAPA DE VTR BPMA'!A:A,'MAPA DE VTR BPMA'!E:E,"",0,-1),"Sem valor")} -> MITSUBISHI | E28: {=IFERROR(XLOOKUP(F28, 'MAPA DE VTR BPMA'!A:A,'MAPA DE VTR BPMA'!F:F,"",0,-1),"Sem valor")} -> ASX | F28: 553959 | G28: {=IFERROR(XLOOKUP(F28, 'MAPA DE VTR BPMA'!A:A,'MAPA DE VTR BPMA'!L:L,"",0,-1),"Sem valor")} -> PBN 7383 | H28: - | I28: {=IFERROR(XLOOKUP(F28, 'MAPA DE VTR BPMA'!A:A,'MAPA DE VTR BPMA'!G:G,"",0,-1),"Sem valor")} -> 2018/2019 | J28: {=IFERROR(XLOOKUP(F28, 'MAPA DE VTR BPMA'!A:A,'MAPA DE VTR BPMA'!B:B,"",0,-1),"Sem valor")} -> 3600247624 | K28: {=IFERROR(XLOOKUP($F28, 'MAPA DE VTR BPMA'!A:A,'MAPA DE VTR BPMA'!O:O,"",0,-1),"Sem valor")} -> 3600212886 | L28: {=IFERROR(XLOOKUP($F28, 'MAPA DE VTR BPMA'!A:A,'MAPA DE VTR BPMA'!N:N,"",0,-1),"Sem valor")} -> 3600247672 | M28: {=IFERROR(XLOOKUP($F28, 'MAPA DE VTR BPMA'!A:A,'MAPA DE VTR BPMA'!I:I,"",0,-1),"Sem valor")} | N28: {=IFERROR(XLOOKUP($F28, 'MAPA DE VTR BPMA'!A:A,'MAPA DE VTR BPMA'!J:J,"",0,-1),"Sem valor")} -> Disponível | O28: {=IFERROR(XLOOKUP($F28, 'MAPA DE VTR BPMA'!A:A,'MAPA DE VTR BPMA'!H:H,"",0,-1),"Sem valor")} -> SEDE BPMA
A29: Total de Mitsubishi ASX | B29: =B28 -> 1
A30: BPMA | B30: 1 | C30: {=IFERROR(XLOOKUP(F30, 'MAPA DE VTR BPMA'!A:A,'MAPA DE VTR BPMA'!D:D,"",0,-1),"Sem valor")} -> OPERACIONAL | D30: {=IFERROR(XLOOKUP(F30, 'MAPA DE VTR BPMA'!A:A,'MAPA DE VTR BPMA'!E:E,"",0,-1),"Sem valor")} -> MITSUBISHI | E30: {=IFERROR(XLOOKUP(F30, 'MAPA DE VTR BPMA'!A:A,'MAPA DE VTR BPMA'!F:F,"",0,-1),"Sem valor")} -> L200 TRITON | F30: 554544 | G30: {=IFERROR(XLOOKUP(F30, 'MAPA DE VTR BPMA'!A:A,'MAPA DE VTR BPMA'!L:L,"",0,-1),"Sem valor")} -> SSF8H49 | H30: - | I30: {=IFERROR(XLOOKUP(F30, 'MAPA DE VTR BPMA'!A:A,'MAPA DE VTR BPMA'!G:G,"",0,-1),"Sem valor")} -> 2023 | J30: {=IFERROR(XLOOKUP(F30, 'MAPA DE VTR BPMA'!A:A,'MAPA DE VTR BPMA'!B:B,"",0,-1),"Sem valor")} -> 200199058 | K30: {=IFERROR(XLOOKUP($F30, 'MAPA DE VTR BPMA'!A:A,'MAPA DE VTR BPMA'!O:O,"",0,-1),"Sem valor")} -> INDEFINIDO | L30: {=IFERROR(XLOOKUP($F30, 'MAPA DE VTR BPMA'!A:A,'MAPA DE VTR BPMA'!N:N,"",0,-1),"Sem valor")} -> NÃO TEM TOMBAMENTO | M30: {=IFERROR(XLOOKUP($F30, 'MAPA DE VTR BPMA'!A:A,'MAPA DE VTR BPMA'!I:I,"",0,-1),"Sem valor")} | N30: {=IFERROR(XLOOKUP($F30, 'MAPA DE VTR BPMA'!A:A,'MAPA DE VTR BPMA'!J:J,"",0,-1),"Sem valor")} -> Disponível | O30: {=IFERROR(XLOOKUP($F30, 'MAPA DE VTR BPMA'!A:A,'MAPA DE VTR BPMA'!H:H,"",0,-1),"Sem valor")} -> SEDE BPMA
A31: BPMA | B31: 2 | C31: {=IFERROR(XLOOKUP(F31, 'MAPA DE VTR BPMA'!A:A,'MAPA DE VTR BPMA'!D:D,"",0,-1),"Sem valor")} -> OPERACIONAL | D31: {=IFERROR(XLOOKUP(F31, 'MAPA DE VTR BPMA'!A:A,'MAPA DE VTR BPMA'!E:E,"",0,-1),"Sem valor")} -> MITSUBISHI | E31: {=IFERROR(XLOOKUP(F31, 'MAPA DE VTR BPMA'!A:A,'MAPA DE VTR BPMA'!F:F,"",0,-1),"Sem valor")} -> L200 TRITON | F31: 554545 | G31: {=IFERROR(XLOOKUP(F31, 'MAPA DE VTR BPMA'!A:A,'MAPA DE VTR BPMA'!L:L,"",0,-1),"Sem valor")} -> SSF8H42 | H31: - | I31: {=IFERROR(XLOOKUP(F31, 'MAPA DE VTR BPMA'!A:A,'MAPA DE VTR BPMA'!G:G,"",0,-1),"Sem valor")} -> 2023 | J31: {=IFERROR(XLOOKUP(F31, 'MAPA DE VTR BPMA'!A:A,'MAPA DE VTR BPMA'!B:B,"",0,-1),"Sem valor")} -> 200199059 | K31: {=IFERROR(XLOOKUP($F31, 'MAPA DE VTR BPMA'!A:A,'MAPA DE VTR BPMA'!O:O,"",0,-1),"Sem valor")} -> INDEFINIDO | L31: {=IFERROR(XLOOKUP($F31, 'MAPA DE VTR BPMA'!A:A,'MAPA DE VTR BPMA'!N:N,"",0,-1),"Sem valor")} -> NÃO TEM TOMBAMENTO | M31: {=IFERROR(XLOOKUP($F31, 'MAPA DE VTR BPMA'!A:A,'MAPA DE VTR BPMA'!I:I,"",0,-1),"Sem valor")} | N31: {=IFERROR(XLOOKUP($F31, 'MAPA DE VTR BPMA'!A:A,'MAPA DE VTR BPMA'!J:J,"",0,-1),"Sem valor")} -> Disponível | O31: {=IFERROR(XLOOKUP($F31, 'MAPA DE VTR BPMA'!A:A,'MAPA DE VTR BPMA'!H:H,"",0,-1),"Sem valor")} -> SEDE BPMA
A32: BPMA | B32: 3 | C32: {=IFERROR(XLOOKUP(F32, 'MAPA DE VTR BPMA'!A:A,'MAPA DE VTR BPMA'!D:D,"",0,-1),"Sem valor")} -> OPERACIONAL | D32: {=IFERROR(XLOOKUP(F32, 'MAPA DE VTR BPMA'!A:A,'MAPA DE VTR BPMA'!E:E,"",0,-1),"Sem valor")} -> MITSUBISHI | E32: {=IFERROR(XLOOKUP(F32, 'MAPA DE VTR BPMA'!A:A,'MAPA DE VTR BPMA'!F:F,"",0,-1),"Sem valor")} -> L200 TRITON GLS AT | F32: 554434 | G32: {=IFERROR(XLOOKUP(F32, 'MAPA DE VTR BPMA'!A:A,'MAPA DE VTR BPMA'!L:L,"",0,-1),"Sem valor")} -> SGV6D61 | H32: - | I32: {=IFERROR(XLOOKUP(F32, 'MAPA DE VTR BPMA'!A:A,'MAPA DE VTR BPMA'!G:G,"",0,-1),"Sem valor")} -> 2023 | J32: {=IFERROR(XLOOKUP(F32, 'MAPA DE VTR BPMA'!A:A,'MAPA DE VTR BPMA'!B:B,"",0,-1),"Sem valor")} -> 3600291084 | K32: {=IFERROR(XLOOKUP($F32, 'MAPA DE VTR BPMA'!A:A,'MAPA DE VTR BPMA'!O:O,"",0,-1),"Sem valor")} -> 3600213152 | L32: {=IFERROR(XLOOKUP($F32, 'MAPA DE VTR BPMA'!A:A,'MAPA DE VTR BPMA'!N:N,"",0,-1),"Sem valor")} -> 3600291142 | M32: {=IFERROR(XLOOKUP($F32, 'MAPA DE VTR BPMA'!A:A,'MAPA DE VTR BPMA'!I:I,"",0,-1),"Sem valor")} | N32: {=IFERROR(XLOOKUP($F32, 'MAPA DE VTR BPMA'!A:A,'MAPA DE VTR BPMA'!J:J,"",0,-1),"Sem valor")} -> Disponível | O32: {=IFERROR(XLOOKUP($F32, 'MAPA DE VTR BPMA'!A:A,'MAPA DE VTR BPMA'!H:H,"",0,-1),"Sem valor")} -> SEDE BPMA
A33: BPMA | B33: 4 | C33: {=IFERROR(XLOOKUP(F33, 'MAPA DE VTR BPMA'!A:A,'MAPA DE VTR BPMA'!D:D,"",0,-1),"Sem valor")} -> OPERACIONAL | D33: {=IFERROR(XLOOKUP(F33, 'MAPA DE VTR BPMA'!A:A,'MAPA DE VTR BPMA'!E:E,"",0,-1),"Sem valor")} -> MITSUBISHI | E33: {=IFERROR(XLOOKUP(F33, 'MAPA DE VTR BPMA'!A:A,'MAPA DE VTR BPMA'!F:F,"",0,-1),"Sem valor")} -> L200 TRITON GLS AT | F33: 554435 | G33: {=IFERROR(XLOOKUP(F33, 'MAPA DE VTR BPMA'!A:A,'MAPA DE VTR BPMA'!L:L,"",0,-1),"Sem valor")} -> SGV6D84 | H33: - | I33: {=IFERROR(XLOOKUP(F33, 'MAPA DE VTR BPMA'!A:A,'MAPA DE VTR BPMA'!G:G,"",0,-1),"Sem valor")} -> 2023 | J33: {=IFERROR(XLOOKUP(F33, 'MAPA DE VTR BPMA'!A:A,'MAPA DE VTR BPMA'!B:B,"",0,-1),"Sem valor")} -> 3600291077 | K33: {=IFERROR(XLOOKUP($F33, 'MAPA DE VTR BPMA'!A:A,'MAPA DE VTR BPMA'!O:O,"",0,-1),"Sem valor")} -> 3600212032 | L33: {=IFERROR(XLOOKUP($F33, 'MAPA DE VTR BPMA'!A:A,'MAPA DE VTR BPMA'!N:N,"",0,-1),"Sem valor")} -> 3600291141 | M33: {=IFERROR(XLOOKUP($F33, 'MAPA DE VTR BPMA'!A:A,'MAPA DE VTR BPMA'!I:I,"",0,-1),"Sem valor")} | N33: {=IFERROR(XLOOKUP($F33, 'MAPA DE VTR BPMA'!A:A,'MAPA DE VTR BPMA'!J:J,"",0,-1),"Sem valor")} -> Indisponível | O33: {=IFERROR(XLOOKUP($F33, 'MAPA DE VTR BPMA'!A:A,'MAPA DE VTR BPMA'!H:H,"",0,-1),"Sem valor")} -> SEDE BPMA
A34: BPMA | B34: 5 | C34: {=IFERROR(XLOOKUP(F34, 'MAPA DE VTR BPMA'!A:A,'MAPA DE VTR BPMA'!D:D,"",0,-1),"Sem valor")} -> OPERACIONAL | D34: {=IFERROR(XLOOKUP(F34, 'MAPA DE VTR BPMA'!A:A,'MAPA DE VTR BPMA'!E:E,"",0,-1),"Sem valor")} -> MITSUBISHI | E34: {=IFERROR(XLOOKUP(F34, 'MAPA DE VTR BPMA'!A:A,'MAPA DE VTR BPMA'!F:F,"",0,-1),"Sem valor")} -> L200 TRITON GLS AT | F34: 554437 | G34: {=IFERROR(XLOOKUP(F34, 'MAPA DE VTR BPMA'!A:A,'MAPA DE VTR BPMA'!L:L,"",0,-1),"Sem valor")} -> SGV6D85 | H34: - | I34: {=IFERROR(XLOOKUP(F34, 'MAPA DE VTR BPMA'!A:A,'MAPA DE VTR BPMA'!G:G,"",0,-1),"Sem valor")} -> 2023 | J34: {=IFERROR(XLOOKUP(F34, 'MAPA DE VTR BPMA'!A:A,'MAPA DE VTR BPMA'!B:B,"",0,-1),"Sem valor")} -> 3600291073 | K34: {=IFERROR(XLOOKUP($F34, 'MAPA DE VTR BPMA'!A:A,'MAPA DE VTR BPMA'!O:O,"",0,-1),"Sem valor")} -> 3600213164 | L34: {=IFERROR(XLOOKUP($F34, 'MAPA DE VTR BPMA'!A:A,'MAPA DE VTR BPMA'!N:N,"",0,-1),"Sem valor")} -> 3600291135 | M34: {=IFERROR(XLOOKUP($F34, 'MAPA DE VTR BPMA'!A:A,'MAPA DE VTR BPMA'!I:I,"",0,-1),"Sem valor")} | N34: {=IFERROR(XLOOKUP($F34, 'MAPA DE VTR BPMA'!A:A,'MAPA DE VTR BPMA'!J:J,"",0,-1),"Sem valor")} -> Disponível | O34: {=IFERROR(XLOOKUP($F34, 'MAPA DE VTR BPMA'!A:A,'MAPA DE VTR BPMA'!H:H,"",0,-1),"Sem valor")} -> INDEFINIDO
A35: BPMA | B35: 6 | C35: {=IFERROR(XLOOKUP(F35, 'MAPA DE VTR BPMA'!A:A,'MAPA DE VTR BPMA'!D:D,"",0,-1),"Sem valor")} -> OPERACIONAL | D35: {=IFERROR(XLOOKUP(F35, 'MAPA DE VTR BPMA'!A:A,'MAPA DE VTR BPMA'!E:E,"",0,-1),"Sem valor")} -> MITSUBISHI | E35: {=IFERROR(XLOOKUP(F35, 'MAPA DE VTR BPMA'!A:A,'MAPA DE VTR BPMA'!F:F,"",0,-1),"Sem valor")} -> L200 TRITON GLS AT | F35: 554439 | G35: {=IFERROR(XLOOKUP(F35, 'MAPA DE VTR BPMA'!A:A,'MAPA DE VTR BPMA'!L:L,"",0,-1),"Sem valor")} -> SGU9C96 | H35: - | I35: {=IFERROR(XLOOKUP(F35, 'MAPA DE VTR BPMA'!A:A,'MAPA DE VTR BPMA'!G:G,"",0,-1),"Sem valor")} -> 2023 | J35: {=IFERROR(XLOOKUP(F35, 'MAPA DE VTR BPMA'!A:A,'MAPA DE VTR BPMA'!B:B,"",0,-1),"Sem valor")} -> 3600291050 | K35: {=IFERROR(XLOOKUP($F35, 'MAPA DE VTR BPMA'!A:A,'MAPA DE VTR BPMA'!O:O,"",0,-1),"Sem valor")} -> 3600212006 | L35: {=IFERROR(XLOOKUP($F35, 'MAPA DE VTR BPMA'!A:A,'MAPA DE VTR BPMA'!N:N,"",0,-1),"Sem valor")} -> 3600291139 | M35: {=IFERROR(XLOOKUP($F35, 'MAPA DE VTR BPMA'!A:A,'MAPA DE VTR BPMA'!I:I,"",0,-1),"Sem valor")} | N35: {=IFERROR(XLOOKUP($F35, 'MAPA DE VTR BPMA'!A:A,'MAPA DE VTR BPMA'!J:J,"",0,-1),"Sem valor")} -> Disponível | O35: {=IFERROR(XLOOKUP($F35, 'MAPA DE VTR BPMA'!A:A,'MAPA DE VTR BPMA'!H:H,"",0,-1),"Sem valor")} -> SEDE BPMA
